Workbook

Sheet 00 ACC DETAILS 01
B2: ACCOUNT DETAILS | F2: REQUESTED BY
B3: Lot No. | C3: 2512-C-10B | F3: Name of Requester
B4: Division | C4: 10 | F4: First Name | G4: =IF(ISBLANK(C6),C11,C7)
B5: Name of IA | C5: BAGONG BUHAY IA | F5: Middle Name | G5: =IF(ISBLANK(C6),C12,C8)
A6: * | B6: Name of Land Owner | F6: Surname | G6: =IF(ISBLANK(C6),C13,C9)
B7: First Name | C7: TIBURCIO | F7: Address of Requester
B8: Middle Name | F8: Barangay | G8: =IF(ISBLANK(C6),C23,C19)
B9: Surname | C9: PUNZALAN | F9: Municipality/City | G9: =IF(ISBLANK(C6),C24,C20)
B10: Name of Farmer/Land Tiller | F10: Province | G10: =IF(ISBLANK(C6),C25,C21)
B11: First Name | C11: FERNANDO
B12: Middle Name
B13: Surname | C13: SILVESTRE
B14: Location of Lot
B15: Baranggay
B16: Municipality/City
B17: Province
B18: Address of Land Owner
B19: Barangay
B20: Municipality/City
B21: Province
B22: Address of Farmer/Land Tiller
B23: Baranggay
B24: Municipality/City
B25: Province
A28: IRRIGATION FEE REGISTRY (IFR)
B29: Wet/Dry | C29: Year | D29: Area
A30: 1 | B30: DRY | C30: 1975 | D30: 0.47 | E30: =IF(ISBLANK(B30),0,IF(C30<2000,RIGHT(C30,2),C30)&"-"&IF(B30="wet","W","D"))
A31: 2 | B31: DRY | C31: 1976 | D31: 0.47 | E31: =IF(ISBLANK(B31),0,IF(C31<2000,RIGHT(C31,2),C31)&"-"&IF(B31="wet","W","D"))
A32: 3 | B32: DRY | C32: 1977 | D32: 0.47 | E32: =IF(ISBLANK(B32),0,IF(C32<2000,RIGHT(C32,2),C32)&"-"&IF(B32="wet","W","D"))
A33: 4 | B33: DRY | C33: 1978 | D33: 0.47 | E33: =IF(ISBLANK(B33),0,IF(C33<2000,RIGHT(C33,2),C33)&"-"&IF(B33="wet","W","D"))
A34: 5 | B34: DRY | C34: 1979 | D34: 0.47 | E34: =IF(ISBLANK(B34),0,IF(C34<2000,RIGHT(C34,2),C34)&"-"&IF(B34="wet","W","D"))
A35: 6 | B35: DRY | C35: 1980 | D35: 0.47 | E35: =IF(ISBLANK(B35),0,IF(C35<2000,RIGHT(C35,2),C35)&"-"&IF(B35="wet","W","D"))
A36: 7 | B36: DRY | C36: 1981 | D36: 0.47 | E36: =IF(ISBLANK(B36),0,IF(C36<2000,RIGHT(C36,2),C36)&"-"&IF(B36="wet","W","D"))
A37: 8 | B37: DRY | C37: 1982 | D37: 0.47 | E37: =IF(ISBLANK(B37),0,IF(C37<2000,RIGHT(C37,2),C37)&"-"&IF(B37="wet","W","D"))
A38: 9 | B38: DRY | C38: 1983 | D38: 0.47 | E38: =IF(ISBLANK(B38),0,IF(C38<2000,RIGHT(C38,2),C38)&"-"&IF(B38="wet","W","D"))
A39: 10 | B39: DRY | C39: 1984 | D39: 0.47 | E39: =IF(ISBLANK(B39),0,IF(C39<2000,RIGHT(C39,2),C39)&"-"&IF(B39="wet","W","D"))
A40: 11 | B40: DRY | C40: 1985 | D40: 0.47 | E40: =IF(ISBLANK(B40),0,IF(C40<2000,RIGHT(C40,2),C40)&"-"&IF(B40="wet","W","D"))
A41: 12 | B41: DRY | C41: 1986 | D41: 0.47 | E41: =IF(ISBLANK(B41),0,IF(C41<2000,RIGHT(C41,2),C41)&"-"&IF(B41="wet","W","D"))
... A66: 37 | B66: DRY | C66: 2012 | D66: 0.47 | E66: =IF(ISBLANK(B66),0,IF(C66<2000,RIGHT(C66,2),C66)&"-"&IF(B66="wet","W","D"))
A67: 38 | E67: =IF(ISBLANK(B67),0,IF(C67<2000,RIGHT(C67,2),C67)&"-"&IF(B67="wet","W","D"))
...

Sheet 01 SOA 01
A2: REPUBLIC OF THE PHILIPPINES
A3: NATIONAL IRRIGATION ADMINISTRATION
A4: REGIONAL OFFICE NO. III (CENTRAL LUZON)
A5: BULACAN IRRIGATION MANAGEMENT OFFICE
A9: STATEMENT OF ACCOUNT
A10: ="as of "&TEXT(TODAY(),"mmmm dd, yyyy")
A12: FARMER CODE NO.: | F12: WRFT Div. : | G12: ='00 ACC DETAILS 01'!C4&" - "&'00 ACC DETAILS 01'!C5
A13: Lot No.: | C13: ='00 ACC DETAILS 01'!C3 | F13: Area:. | G13: {=LOOKUP(2,0/(A17:A99),A17:A99)}
A14: Name of Landowner: | C14: =IF(ISBLANK('00 ACC DETAILS 01'!C8),'00 ACC DETAILS 01'!C7&" "&'00 ACC DETAILS 01'!C9,'00 ACC DETAILS 01'!C7&" "&'00 ACC DETAILS 01'!C8&" "&'00 ACC DETAILS 01'!C9) | E14: Address:
A15: Name of Farmers: | C15: =IF(ISBLANK('00 ACC DETAILS 01'!C12),'00 ACC DETAILS 01'!C11&" "&'00 ACC DETAILS 01'!C13,'00 ACC DETAILS 01'!C11&" "&'00 ACC DETAILS 01'!C12&" "&'00 ACC DETAILS 01'!C13) | E15: Address:
A16: Area | B16: C. S. | C16: Rate | D16: Principal | E16: %Penalty | F16: Penalty(Cash) | G16: Total
A17: =IFERROR((LOOKUP(MATCH(B17,'00 ACC DETAILS 01'!$E$30:$E$112,0),'00 ACC DETAILS 01'!$A$30:$A$112,'00 ACC DETAILS 01'!$D$30:$D$112)),0) | B17: 75-W | C17: =15*100 | D17: =A17*C17 | E17: =E19+12 | F17: =D17*E17/100 | G17: =D17+F17
A18: =IFERROR((LOOKUP(MATCH(B18,'00 ACC DETAILS 01'!$E$30:$E$112,0),'00 ACC DETAILS 01'!$A$30:$A$112,'00 ACC DETAILS 01'!$D$30:$D$112)),0) | B18: 76-D | C18: =15*150 | D18: =A18*C18 | E18: =E20+12 | F18: =D18*E18/100 | G18: =D18+F18
A19: =IFERROR((LOOKUP(MATCH(B19,'00 ACC DETAILS 01'!$E$30:$E$112,0),'00 ACC DETAILS 01'!$A$30:$A$112,'00 ACC DETAILS 01'!$D$30:$D$112)),0) | B19: 76-W | C19: =C17 | D19: =A19*C19 | E19: =E20+12 | F19: =D19*E19/100 | G19: =D19+F19
A20: =IFERROR((LOOKUP(MATCH(B20,'00 ACC DETAILS 01'!$E$30:$E$112,0),'00 ACC DETAILS 01'!$A$30:$A$112,'00 ACC DETAILS 01'!$D$30:$D$112)),0) | B20: 77-D | C20: =C18 | D20: =A20*C20 | E20: =E22+12 | F20: =D20*E20/100 | G20: =D20+F20
A21: =IFERROR((LOOKUP(MATCH(B21,'00 ACC DETAILS 01'!$E$30:$E$112,0),'00 ACC DETAILS 01'!$A$30:$A$112,'00 ACC DETAILS 01'!$D$30:$D$112)),0) | B21: 77-W | C21: =C19 | D21: =A21*C21 | E21: =E22+12 | F21: =D21*E21/100 | G21: =D21+F21
A22: =IFERROR((LOOKUP(MATCH(B22,'00 ACC DETAILS 01'!$E$30:$E$112,0),'00 ACC DETAILS 01'!$A$30:$A$112,'00 ACC DETAILS 01'!$D$30:$D$112)),0) | B22: 78-D | C22: =C20 | D22: =A22*C22 | E22: =E24+6 | F22: =D22*E22/100 | G22: =D22+F22
A23: =IFERROR((LOOKUP(MATCH(B23,'00 ACC DETAILS 01'!$E$30:$E$112,0),'00 ACC DETAILS 01'!$A$30:$A$112,'00 ACC DETAILS 01'!$D$30:$D$112)),0) | B23: 78-W | C23: =C21 | D23: =A23*C23 | E23: =E24+6 | F23: =D23*E23/100 | G23: =D23+F23
A24: =IFERROR((LOOKUP(MATCH(B24,'00 ACC DETAILS 01'!$E$30:$E$112,0),'00 ACC DETAILS 01'!$A$30:$A$112,'00 ACC DETAILS 01'!$D$30:$D$112)),0) | B24: 79-D | C24: =C22 | D24: =A24*C24 | E24: =E25+6 | F24: =D24*E24/100 | G24: =D24+F24
A25: =IFERROR((LOOKUP(MATCH(B25,'00 ACC DETAILS 01'!$E$30:$E$112,0),'00 ACC DETAILS 01'!$A$30:$A$112,'00 ACC DETAILS 01'!$D$30:$D$112)),0) | B25: 79-W | C25: =C23 | D25: =A25*C25 | E25: =E26+6 | F25: =D25*E25/100 | G25: =D25+F25
A26: =IFERROR((LOOKUP(MATCH(B26,'00 ACC DETAILS 01'!$E$30:$E$112,0),'00 ACC DETAILS 01'!$A$30:$A$112,'00 ACC DETAILS 01'!$D$30:$D$112)),0) | B26: 80-D | C26: =C24 | D26: =A26*C26 | E26: =E27+6 | F26: =D26*E26/100 | G26: =D26+F26
A27: =IFERROR((LOOKUP(MATCH(B27,'00 ACC DETAILS 01'!$E$30:$E$112,0),'00 ACC DETAILS 01'!$A$30:$A$112,'00 ACC DETAILS 01'!$D$30:$D$112)),0) | B27: 80-W | C27: =C25 | D27: =A27*C27 | E27: =E28+6 | F27: =D27*E27/100 | G27: =D27+F27
A28: =IFERROR((LOOKUP(MATCH(B28,'00 ACC DETAILS 01'!$E$30:$E$112,0),'00 ACC DETAILS 01'!$A$30:$A$112,'00 ACC DETAILS 01'!$D$30:$D$112)),0) | B28: 81-D | C28: =C26 | D28: =A28*C28 | E28: =E29+6 | F28: =D28*E28/100 | G28: =D28+F28
A29: =IFERROR((LOOKUP(MATCH(B29,'00 ACC DETAILS 01'!$E$30:$E$112,0),'00 ACC DETAILS 01'!$A$30:$A$112,'00 ACC DETAILS 01'!$D$30:$D$112)),0) | B29: 81-W | C29: =C27 | D29: =A29*C29 | E29: =E30+6 | F29: =D29*E29/100 | G29: =D29+F29
A30: =IFERROR((LOOKUP(MATCH(B30,'00 ACC DETAILS 01'!$E$30:$E$112,0),'00 ACC DETAILS 01'!$A$30:$A$112,'00 ACC DETAILS 01'!$D$30:$D$112)),0) | B30: 82-D | C30: =C28 | D30: =A30*C30 | E30: =E31+6 | F30: =D30*E30/100 | G30: =D30+F30
A31: =IFERROR((LOOKUP(MATCH(B31,'00 ACC DETAILS 01'!$E$30:$E$112,0),'00 ACC DETAILS 01'!$A$30:$A$112,'00 ACC DETAILS 01'!$D$30:$D$112)),0) | B31: 82-W | C31: =C29 | D31: =A31*C31 | E31: =E32+6 | F31: =D31*E31/100 | G31: =D31+F31
A32: =IFERROR((LOOKUP(MATCH(B32,'00 ACC DETAILS 01'!$E$30:$E$112,0),'00 ACC DETAILS 01'!$A$30:$A$112,'00 ACC DETAILS 01'!$D$30:$D$112)),0) | B32: 83-D | C32: =C30 | D32: =A32*C32 | E32: =E33+6 | F32: =D32*E32/100 | G32: =D32+F32
A33: =IFERROR((LOOKUP(MATCH(B33,'00 ACC DETAILS 01'!$E$30:$E$112,0),'00 ACC DETAILS 01'!$A$30:$A$112,'00 ACC DETAILS 01'!$D$30:$D$112)),0) | B33: 83-W | C33: =C31 | D33: =A33*C33 | E33: =E34+6 | F33: =D33*E33/100 | G33: =D33+F33
A34: =IFERROR((LOOKUP(MATCH(B34,'00 ACC DETAILS 01'!$E$30:$E$112,0),'00 ACC DETAILS 01'!$A$30:$A$112,'00 ACC DETAILS 01'!$D$30:$D$112)),0) | B34: 84-D | C34: =C32 | D34: =A34*C34 | E34: =E35+6 | F34: =D34*E34/100 | G34: =D34+F34
... A61: =IFERROR((LOOKUP(MATCH(B61,'00 ACC DETAILS 01'!$E$30:$E$112,0),'00 ACC DETAILS 01'!$A$30:$A$112,'00 ACC DETAILS 01'!$D$30:$D$112)),0) | B61: 97-W | C61: =C59 | D61: =A61*C61 | E61: =E62+6 | F61: =D61*E61/100 | G61: =D61+F61
A62: =IFERROR((LOOKUP(MATCH(B62,'00 ACC DETAILS 01'!$E$30:$E$112,0),'00 ACC DETAILS 01'!$A$30:$A$112,'00 ACC DETAILS 01'!$D$30:$D$112)),0) | B62: 98-D | C62: 0 | D62: =A62*C62 | E62: =E63+6 | F62: =D62*E62/100 | G62: =D62+F62
A63: =IFERROR((LOOKUP(MATCH(B63,'00 ACC DETAILS 01'!$E$30:$E$112,0),'00 ACC DETAILS 01'!$A$30:$A$112,'00 ACC DETAILS 01'!$D$30:$D$112)),0) | B63: 98-W | C63: 400 | D63: =A63*C63 | E63: =E64+6 | F63: =D63*E63/100 | G63: =D63+F63
A64: =IFERROR((LOOKUP(MATCH(B64,'00 ACC DETAILS 01'!$E$30:$E$112,0),'00 ACC DETAILS 01'!$A$30:$A$112,'00 ACC DETAILS 01'!$D$30:$D$112)),0) | B64: 99-D | C64: 600 | D64: =A64*C64 | E64: =E65+6 | F64: =D64*E64/100 | G64: =D64+F64
A65: =IFERROR((LOOKUP(MATCH(B65,'00 ACC DETAILS 01'!$E$30:$E$112,0),'00 ACC DETAILS 01'!$A$30:$A$112,'00 ACC DETAILS 01'!$D$30:$D$112)),0) | B65: 99-W | C65: 450 | D65: =A65*C65 | E65: =E66+6 | F65: =D65*E65/100 | G65: =D65+F65
A66: =IFERROR((LOOKUP(MATCH(B66,'00 ACC DETAILS 01'!$E$30:$E$112,0),'00 ACC DETAILS 01'!$A$30:$A$112,'00 ACC DETAILS 01'!$D$30:$D$112)),0) | B66: 2000-D | C66: 750 | D66: =A66*C66 | E66: =E67+6 | F66: =D66*E66/100 | G66: =D66+F66
A67: =IFERROR((LOOKUP(MATCH(B67,'00 ACC DETAILS 01'!$E$30:$E$112,0),'00 ACC DETAILS 01'!$A$30:$A$112,'00 ACC DETAILS 01'!$D$30:$D$112)),0) | B67: 2000-W | C67: =C65 | D67: =A67*C67 | E67: =E68+6 | F67: =D67*E67/100 | G67: =D67+F67
A68: =IFERROR((LOOKUP(MATCH(B68,'00 ACC DETAILS 01'!$E$30:$E$112,0),'00 ACC DETAILS 01'!$A$30:$A$112,'00 ACC DETAILS 01'!$D$30:$D$112)),0) | B68: 2001-D | C68: =C66 | D68: =A68*C68 | E68: =E69+6 | F68: =D68*E68/100 | G68: =D68+F68
A69: =IFERROR((LOOKUP(MATCH(B69,'00 ACC DETAILS 01'!$E$30:$E$112,0),'00 ACC DETAILS 01'!$A$30:$A$112,'00 ACC DETAILS 01'!$D$30:$D$112)),0) | B69: 2001-W | C69: =C61 | D69: =A69*C69 | E69: =E70+6 | F69: =D69*E69/100 | G69: =D69+F69
A70: =IFERROR((LOOKUP(MATCH(B70,'00 ACC DETAILS 01'!$E$30:$E$112,0),'00 ACC DETAILS 01'!$A$30:$A$112,'00 ACC DETAILS 01'!$D$30:$D$112)),0) | B70: 2002-D | C70: =C60 | D70: =A70*C70 | E70: =E71+6 | F70: =D70*E70/100 | G70: =D70+F70
A71: =IFERROR((LOOKUP(MATCH(B71,'00 ACC DETAILS 01'!$E$30:$E$112,0),'00 ACC DETAILS 01'!$A$30:$A$112,'00 ACC DETAILS 01'!$D$30:$D$112)),0) | B71: 2002-W | C71: =C69 | D71: =A71*C71 | E71: =E72+6 | F71: =D71*E71/100 | G71: =D71+F71
...

Sheet 00 ACC DETAILS 02
B2: ACCOUNT DETAILS
B3: Lot No. | C3: 3809
B4: Division | C4: ='00 ACC DETAILS 01'!C4
B5: Name of IA | C5: ='00 ACC DETAILS 01'!C5
B6: Name of Land Owner
B7: First Name | C7: ='00 ACC DETAILS 01'!C7
B8: Middle Name | C8: ='00 ACC DETAILS 01'!C8
B9: Surname | C9: ='00 ACC DETAILS 01'!C9
B10: Name of Farmer/Land Tiller
B11: First Name | C11: MARCELO
B12: Middle Name
B13: Surname | C13: GUINTO
B14: Location of Lot
B15: Baranggay | C15: ='00 ACC DETAILS 01'!C15
B16: Municipality/City | C16: ='00 ACC DETAILS 01'!C16
B17: Province | C17: ='00 ACC DETAILS 01'!C17
B18: Address of Land Owner
B19: Baranggay | C19: ='00 ACC DETAILS 01'!C19
B20: Municipality/City | C20: ='00 ACC DETAILS 01'!C20
B21: Province | C21: ='00 ACC DETAILS 01'!C21
B22: Address of Farmer/Land Tiller
B23: Baranggay | C23: ='00 ACC DETAILS 01'!C23
B24: Municipality/City | C24: ='00 ACC DETAILS 01'!C24
B25: Province | C25: ='00 ACC DETAILS 01'!C25
A28: IRRIGATION FEE REGISTRY (IFR)
B29: Wet/Dry | C29: Year | D29: Area
A30: 1 | E30: =IF(ISBLANK(B30),0,IF(C30<2000,RIGHT(C30,2),C30)&"-"&IF(B30="wet","W","D"))
A31: 2 | E31: =IF(ISBLANK(B31),0,IF(C31<2000,RIGHT(C31,2),C31)&"-"&IF(B31="wet","W","D"))
A32: 3 | E32: =IF(ISBLANK(B32),0,IF(C32<2000,RIGHT(C32,2),C32)&"-"&IF(B32="wet","W","D"))
A33: 4 | E33: =IF(ISBLANK(B33),0,IF(C33<2000,RIGHT(C33,2),C33)&"-"&IF(B33="wet","W","D"))
A34: 5 | E34: =IF(ISBLANK(B34),0,IF(C34<2000,RIGHT(C34,2),C34)&"-"&IF(B34="wet","W","D"))
A35: 6 | E35: =IF(ISBLANK(B35),0,IF(C35<2000,RIGHT(C35,2),C35)&"-"&IF(B35="wet","W","D"))
A36: 7 | E36: =IF(ISBLANK(B36),0,IF(C36<2000,RIGHT(C36,2),C36)&"-"&IF(B36="wet","W","D"))
A37: 8 | E37: =IF(ISBLANK(B37),0,IF(C37<2000,RIGHT(C37,2),C37)&"-"&IF(B37="wet","W","D"))
A38: 9 | E38: =IF(ISBLANK(B38),0,IF(C38<2000,RIGHT(C38,2),C38)&"-"&IF(B38="wet","W","D"))
A39: 10 | E39: =IF(ISBLANK(B39),0,IF(C39<2000,RIGHT(C39,2),C39)&"-"&IF(B39="wet","W","D"))
A40: 11 | E40: =IF(ISBLANK(B40),0,IF(C40<2000,RIGHT(C40,2),C40)&"-"&IF(B40="wet","W","D"))
A41: 12 | E41: =IF(ISBLANK(B41),0,IF(C41<2000,RIGHT(C41,2),C41)&"-"&IF(B41="wet","W","D"))
... A112: 83 | E112: =IF(ISBLANK(B112),0,IF(C112<2000,RIGHT(C112,2),C112)&"-"&IF(B112="wet","W","D"))

Sheet 01 SOA 02
A11: STATEMENT OF ACCOUNT
A12: ="as of "&TEXT(TODAY(),"mmmm dd, yyyy")
A14: FARMER CODE NO.: | F14: WRFT Div. : | G14: ='00 ACC DETAILS 02'!C4&" - "&'00 ACC DETAILS 02'!C5
A15: Lot No.: | C15: ='00 ACC DETAILS 02'!C3 | F15: Area:. | G15: {=IFERROR(0,LOOKUP(2,1/(A19:A101),A19:A101))}
A16: Name of Landowner: | C16: =IF(ISBLANK('00 ACC DETAILS 01'!C8),'00 ACC DETAILS 01'!C7&" "&'00 ACC DETAILS 01'!C9,'00 ACC DETAILS 01'!C7&" "&'00 ACC DETAILS 01'!C8&" "&'00 ACC DETAILS 01'!C9) | E16: Address:
A17: Name of Farmers: | C17: =IF(ISBLANK('00 ACC DETAILS 02'!C12),'00 ACC DETAILS 02'!C11&" "&'00 ACC DETAILS 02'!C13,'00 ACC DETAILS 02'!C11&" "&'00 ACC DETAILS 02'!C12&" "&'00 ACC DETAILS 02'!C13) | E17: Address:
A18: Area | B18: C. S. | C18: Rate | D18: Principal | E18: %Penalty | F18: Penalty(Cash) | G18: Total
A19: =IFERROR((LOOKUP(MATCH(B19,'00 ACC DETAILS 02'!$E$30:$E$112,0),'00 ACC DETAILS 02'!$A$30:$A$112,'00 ACC DETAILS 02'!$D$30:$D$112)),0) | B19: 75-W | C19: =15*100 | D19: =A19*C19 | E19: =E21+12 | F19: =D19*E19/100 | G19: =D19+F19
A20: =IFERROR((LOOKUP(MATCH(B20,'00 ACC DETAILS 02'!$E$30:$E$112,0),'00 ACC DETAILS 02'!$A$30:$A$112,'00 ACC DETAILS 02'!$D$30:$D$112)),0) | B20: 76-D | C20: =15*150 | D20: =A20*C20 | E20: =E22+12 | F20: =D20*E20/100 | G20: =D20+F20
A21: =IFERROR((LOOKUP(MATCH(B21,'00 ACC DETAILS 02'!$E$30:$E$112,0),'00 ACC DETAILS 02'!$A$30:$A$112,'00 ACC DETAILS 02'!$D$30:$D$112)),0) | B21: 76-W | C21: =C19 | D21: =A21*C21 | E21: =E22+12 | F21: =D21*E21/100 | G21: =D21+F21
A22: =IFERROR((LOOKUP(MATCH(B22,'00 ACC DETAILS 02'!$E$30:$E$112,0),'00 ACC DETAILS 02'!$A$30:$A$112,'00 ACC DETAILS 02'!$D$30:$D$112)),0) | B22: 77-D | C22: =C20 | D22: =A22*C22 | E22: =E24+12 | F22: =D22*E22/100 | G22: =D22+F22
A23: =IFERROR((LOOKUP(MATCH(B23,'00 ACC DETAILS 02'!$E$30:$E$112,0),'00 ACC DETAILS 02'!$A$30:$A$112,'00 ACC DETAILS 02'!$D$30:$D$112)),0) | B23: 77-W | C23: =C21 | D23: =A23*C23 | E23: =E24+12 | F23: =D23*E23/100 | G23: =D23+F23
A24: =IFERROR((LOOKUP(MATCH(B24,'00 ACC DETAILS 02'!$E$30:$E$112,0),'00 ACC DETAILS 02'!$A$30:$A$112,'00 ACC DETAILS 02'!$D$30:$D$112)),0) | B24: 78-D | C24: =C22 | D24: =A24*C24 | E24: =E26+6 | F24: =D24*E24/100 | G24: =D24+F24
A25: =IFERROR((LOOKUP(MATCH(B25,'00 ACC DETAILS 02'!$E$30:$E$112,0),'00 ACC DETAILS 02'!$A$30:$A$112,'00 ACC DETAILS 02'!$D$30:$D$112)),0) | B25: 78-W | C25: =C23 | D25: =A25*C25 | E25: =E26+6 | F25: =D25*E25/100 | G25: =D25+F25
A26: =IFERROR((LOOKUP(MATCH(B26,'00 ACC DETAILS 02'!$E$30:$E$112,0),'00 ACC DETAILS 02'!$A$30:$A$112,'00 ACC DETAILS 02'!$D$30:$D$112)),0) | B26: 79-D | C26: =C24 | D26: =A26*C26 | E26: =E27+6 | F26: =D26*E26/100 | G26: =D26+F26
A27: =IFERROR((LOOKUP(MATCH(B27,'00 ACC DETAILS 02'!$E$30:$E$112,0),'00 ACC DETAILS 02'!$A$30:$A$112,'00 ACC DETAILS 02'!$D$30:$D$112)),0) | B27: 79-W | C27: =C25 | D27: =A27*C27 | E27: =E28+6 | F27: =D27*E27/100 | G27: =D27+F27
A28: =IFERROR((LOOKUP(MATCH(B28,'00 ACC DETAILS 02'!$E$30:$E$112,0),'00 ACC DETAILS 02'!$A$30:$A$112,'00 ACC DETAILS 02'!$D$30:$D$112)),0) | B28: 80-D | C28: =C26 | D28: =A28*C28 | E28: =E29+6 | F28: =D28*E28/100 | G28: =D28+F28
A29: =IFERROR((LOOKUP(MATCH(B29,'00 ACC DETAILS 02'!$E$30:$E$112,0),'00 ACC DETAILS 02'!$A$30:$A$112,'00 ACC DETAILS 02'!$D$30:$D$112)),0) | B29: 80-W | C29: =C27 | D29: =A29*C29 | E29: =E30+6 | F29: =D29*E29/100 | G29: =D29+F29
A30: =IFERROR((LOOKUP(MATCH(B30,'00 ACC DETAILS 02'!$E$30:$E$112,0),'00 ACC DETAILS 02'!$A$30:$A$112,'00 ACC DETAILS 02'!$D$30:$D$112)),0) | B30: 81-D | C30: =C28 | D30: =A30*C30 | E30: =E31+6 | F30: =D30*E30/100 | G30: =D30+F30
A31: =IFERROR((LOOKUP(MATCH(B31,'00 ACC DETAILS 02'!$E$30:$E$112,0),'00 ACC DETAILS 02'!$A$30:$A$112,'00 ACC DETAILS 02'!$D$30:$D$112)),0) | B31: 81-W | C31: =C29 | D31: =A31*C31 | E31: =E32+6 | F31: =D31*E31/100 | G31: =D31+F31
A32: =IFERROR((LOOKUP(MATCH(B32,'00 ACC DETAILS 02'!$E$30:$E$112,0),'00 ACC DETAILS 02'!$A$30:$A$112,'00 ACC DETAILS 02'!$D$30:$D$112)),0) | B32: 82-D | C32: =C30 | D32: =A32*C32 | E32: =E33+6 | F32: =D32*E32/100 | G32: =D32+F32
A33: =IFERROR((LOOKUP(MATCH(B33,'00 ACC DETAILS 02'!$E$30:$E$112,0),'00 ACC DETAILS 02'!$A$30:$A$112,'00 ACC DETAILS 02'!$D$30:$D$112)),0) | B33: 82-W | C33: =C31 | D33: =A33*C33 | E33: =E34+6 | F33: =D33*E33/100 | G33: =D33+F33
A34: =IFERROR((LOOKUP(MATCH(B34,'00 ACC DETAILS 02'!$E$30:$E$112,0),'00 ACC DETAILS 02'!$A$30:$A$112,'00 ACC DETAILS 02'!$D$30:$D$112)),0) | B34: 83-D | C34: =C32 | D34: =A34*C34 | E34: =E35+6 | F34: =D34*E34/100 | G34: =D34+F34
A35: =IFERROR((LOOKUP(MATCH(B35,'00 ACC DETAILS 02'!$E$30:$E$112,0),'00 ACC DETAILS 02'!$A$30:$A$112,'00 ACC DETAILS 02'!$D$30:$D$112)),0) | B35: 83-W | C35: =C33 | D35: =A35*C35 | E35: =E36+6 | F35: =D35*E35/100 | G35: =D35+F35
A36: =IFERROR((LOOKUP(MATCH(B36,'00 ACC DETAILS 02'!$E$30:$E$112,0),'00 ACC DETAILS 02'!$A$30:$A$112,'00 ACC DETAILS 02'!$D$30:$D$112)),0) | B36: 84-D | C36: =C34 | D36: =A36*C36 | E36: =E37+6 | F36: =D36*E36/100 | G36: =D36+F36
... A63: =IFERROR((LOOKUP(MATCH(B63,'00 ACC DETAILS 02'!$E$30:$E$112,0),'00 ACC DETAILS 02'!$A$30:$A$112,'00 ACC DETAILS 02'!$D$30:$D$112)),0) | B63: 97-W | C63: =C61 | D63: =A63*C63 | E63: =E64+6 | F63: =D63*E63/100 | G63: =D63+F63
A64: =IFERROR((LOOKUP(MATCH(B64,'00 ACC DETAILS 02'!$E$30:$E$112,0),'00 ACC DETAILS 02'!$A$30:$A$112,'00 ACC DETAILS 02'!$D$30:$D$112)),0) | B64: 98-D | C64: 0 | D64: =A64*C64 | E64: =E65+6 | F64: =D64*E64/100 | G64: =D64+F64
A65: =IFERROR((LOOKUP(MATCH(B65,'00 ACC DETAILS 02'!$E$30:$E$112,0),'00 ACC DETAILS 02'!$A$30:$A$112,'00 ACC DETAILS 02'!$D$30:$D$112)),0) | B65: 98-W | C65: 400 | D65: =A65*C65 | E65: =E66+6 | F65: =D65*E65/100 | G65: =D65+F65
A66: =IFERROR((LOOKUP(MATCH(B66,'00 ACC DETAILS 02'!$E$30:$E$112,0),'00 ACC DETAILS 02'!$A$30:$A$112,'00 ACC DETAILS 02'!$D$30:$D$112)),0) | B66: 99-D | C66: 600 | D66: =A66*C66 | E66: =E67+6 | F66: =D66*E66/100 | G66: =D66+F66
A67: =IFERROR((LOOKUP(MATCH(B67,'00 ACC DETAILS 02'!$E$30:$E$112,0),'00 ACC DETAILS 02'!$A$30:$A$112,'00 ACC DETAILS 02'!$D$30:$D$112)),0) | B67: 99-W | C67: 450 | D67: =A67*C67 | E67: =E68+6 | F67: =D67*E67/100 | G67: =D67+F67
A68: =IFERROR((LOOKUP(MATCH(B68,'00 ACC DETAILS 02'!$E$30:$E$112,0),'00 ACC DETAILS 02'!$A$30:$A$112,'00 ACC DETAILS 02'!$D$30:$D$112)),0) | B68: 2000-D | C68: 750 | D68: =A68*C68 | E68: =E69+6 | F68: =D68*E68/100 | G68: =D68+F68
A69: =IFERROR((LOOKUP(MATCH(B69,'00 ACC DETAILS 02'!$E$30:$E$112,0),'00 ACC DETAILS 02'!$A$30:$A$112,'00 ACC DETAILS 02'!$D$30:$D$112)),0) | B69: 2000-W | C69: =C67 | D69: =A69*C69 | E69: =E70+6 | F69: =D69*E69/100 | G69: =D69+F69
A70: =IFERROR((LOOKUP(MATCH(B70,'00 ACC DETAILS 02'!$E$30:$E$112,0),'00 ACC DETAILS 02'!$A$30:$A$112,'00 ACC DETAILS 02'!$D$30:$D$112)),0) | B70: 2001-D | C70: =C68 | D70: =A70*C70 | E70: =E71+6 | F70: =D70*E70/100 | G70: =D70+F70
A71: =IFERROR((LOOKUP(MATCH(B71,'00 ACC DETAILS 02'!$E$30:$E$112,0),'00 ACC DETAILS 02'!$A$30:$A$112,'00 ACC DETAILS 02'!$D$30:$D$112)),0) | B71: 2001-W | C71: =C63 | D71: =A71*C71 | E71: =E72+6 | F71: =D71*E71/100 | G71: =D71+F71
A72: =IFERROR((LOOKUP(MATCH(B72,'00 ACC DETAILS 02'!$E$30:$E$112,0),'00 ACC DETAILS 02'!$A$30:$A$112,'00 ACC DETAILS 02'!$D$30:$D$112)),0) | B72: 2002-D | C72: =C62 | D72: =A72*C72 | E72: =E73+6 | F72: =D72*E72/100 | G72: =D72+F72
A73: =IFERROR((LOOKUP(MATCH(B73,'00 ACC DETAILS 02'!$E$30:$E$112,0),'00 ACC DETAILS 02'!$A$30:$A$112,'00 ACC DETAILS 02'!$D$30:$D$112)),0) | B73: 2002-W | C73: =C71 | D73: =A73*C73 | E73: =E74+6 | F73: =D73*E73/100 | G73: =D73+F73
A74: =IFERROR((LOOKUP(MATCH(B74,'00 ACC DETAILS 02'!$E$30:$E$112,0),'00 ACC DETAILS 02'!$A$30:$A$112,'00 ACC DETAILS 02'!$D$30:$D$112)),0) | B74: 2003-D | C74: =C72 | D74: =A74*C74 | E74: =E75+6 | F74: =D74*E74/100 | G74: =D74+F74
A75: =IFERROR((LOOKUP(MATCH(B75,'00 ACC DETAILS 02'!$E$30:$E$112,0),'00 ACC DETAILS 02'!$A$30:$A$112,'00 ACC DETAILS 02'!$D$30:$D$112)),0) | B75: 2003-W | C75: =C73 | D75: =A75*C75 | E75: =E76+6 | F75: =D75*E75/100 | G75: =D75+F75
A76: =IFERROR((LOOKUP(MATCH(B76,'00 ACC DETAILS 02'!$E$30:$E$112,0),'00 ACC DETAILS 02'!$A$30:$A$112,'00 ACC DETAILS 02'!$D$30:$D$112)),0) | B76: 2004-D | C76: =C74 | D76: =A76*C76 | E76: =E77+6 | F76: =D76*E76/100 | G76: =D76+F76
A77: =IFERROR((LOOKUP(MATCH(B77,'00 ACC DETAILS 02'!$E$30:$E$112,0),'00 ACC DETAILS 02'!$A$30:$A$112,'00 ACC DETAILS 02'!$D$30:$D$112)),0) | B77: 2004-W | C77: =C75 | D77: =A77*C77 | E77: =E78+6 | F77: =D77*E77/100 | G77: =D77+F77
...

Sheet 00 ACC DETAILS 03
B2: ACCOUNT DETAILS
B3: Lot No. | C3: 3809
B4: Division | C4: ='00 ACC DETAILS 01'!C4
B5: Name of IA | C5: ='00 ACC DETAILS 01'!C5
B6: Name of Land Owner
B7: First Name | C7: ='00 ACC DETAILS 01'!C7
B8: Middle Name | C8: ='00 ACC DETAILS 01'!C8
B9: Surname | C9: ='00 ACC DETAILS 01'!C9
B10: Name of Farmer/Land Tiller
B11: First Name | C11: MARCELO
B12: Middle Name
B13: Surname | C13: GUINTO
B14: Location of Lot
B15: Baranggay | C15: ='00 ACC DETAILS 01'!C15
B16: Municipality/City | C16: ='00 ACC DETAILS 01'!C16
B17: Province | C17: ='00 ACC DETAILS 01'!C17
B18: Address of Land Owner
B19: Baranggay | C19: ='00 ACC DETAILS 01'!C19
B20: Municipality/City | C20: ='00 ACC DETAILS 01'!C20
B21: Province | C21: ='00 ACC DETAILS 01'!C21
B22: Address of Farmer/Land Tiller
B23: Baranggay | C23: ='00 ACC DETAILS 01'!C23
B24: Municipality/City | C24: ='00 ACC DETAILS 01'!C24
B25: Province | C25: ='00 ACC DETAILS 01'!C25
A28: IRRIGATION FEE REGISTRY (IFR)
B29: Wet/Dry | C29: Year | D29: Area
A30: 1 | E30: =IF(ISBLANK(B30),0,IF(C30<2000,RIGHT(C30,2),C30)&"-"&IF(B30="wet","W","D"))
A31: 2 | E31: =IF(ISBLANK(B31),0,IF(C31<2000,RIGHT(C31,2),C31)&"-"&IF(B31="wet","W","D"))
A32: 3 | E32: =IF(ISBLANK(B32),0,IF(C32<2000,RIGHT(C32,2),C32)&"-"&IF(B32="wet","W","D"))
A33: 4 | E33: =IF(ISBLANK(B33),0,IF(C33<2000,RIGHT(C33,2),C33)&"-"&IF(B33="wet","W","D"))
A34: 5 | E34: =IF(ISBLANK(B34),0,IF(C34<2000,RIGHT(C34,2),C34)&"-"&IF(B34="wet","W","D"))
A35: 6 | E35: =IF(ISBLANK(B35),0,IF(C35<2000,RIGHT(C35,2),C35)&"-"&IF(B35="wet","W","D"))
A36: 7 | E36: =IF(ISBLANK(B36),0,IF(C36<2000,RIGHT(C36,2),C36)&"-"&IF(B36="wet","W","D"))
A37: 8 | E37: =IF(ISBLANK(B37),0,IF(C37<2000,RIGHT(C37,2),C37)&"-"&IF(B37="wet","W","D"))
A38: 9 | E38: =IF(ISBLANK(B38),0,IF(C38<2000,RIGHT(C38,2),C38)&"-"&IF(B38="wet","W","D"))
A39: 10 | E39: =IF(ISBLANK(B39),0,IF(C39<2000,RIGHT(C39,2),C39)&"-"&IF(B39="wet","W","D"))
A40: 11 | E40: =IF(ISBLANK(B40),0,IF(C40<2000,RIGHT(C40,2),C40)&"-"&IF(B40="wet","W","D"))
A41: 12 | E41: =IF(ISBLANK(B41),0,IF(C41<2000,RIGHT(C41,2),C41)&"-"&IF(B41="wet","W","D"))
... A112: 83 | E112: =IF(ISBLANK(B112),0,IF(C112<2000,RIGHT(C112,2),C112)&"-"&IF(B112="wet","W","D"))

Sheet 01 SOA 03
A11: STATEMENT OF ACCOUNT
A12: ="as of "&TEXT(TODAY(),"mmmm dd, yyyy")
A14: FARMER CODE NO.: | F14: WRFT Div. : | G14: ='00 ACC DETAILS 03'!C4&" - "&'00 ACC DETAILS 03'!C5
A15: Lot No.: | C15: ='00 ACC DETAILS 03'!C3 | F15: Area:. | G15: {=IFERROR(0,LOOKUP(2,1/(A19:A101),A19:A101))}
A16: Name of Landowner: | C16: =IF(ISBLANK('00 ACC DETAILS 01'!C8),'00 ACC DETAILS 01'!C7&" "&'00 ACC DETAILS 01'!C9,'00 ACC DETAILS 01'!C7&" "&'00 ACC DETAILS 01'!C8&" "&'00 ACC DETAILS 01'!C9) | E16: Address:
A17: Name of Farmers: | C17: =IF(ISBLANK('00 ACC DETAILS 03'!C12),'00 ACC DETAILS 03'!C11&" "&'00 ACC DETAILS 03'!C13,'00 ACC DETAILS 03'!C11&" "&'00 ACC DETAILS 03'!C12&" "&'00 ACC DETAILS 03'!C13) | E17: Address:
A18: Area | B18: C. S. | C18: Rate | D18: Principal | E18: %Penalty | F18: Penalty(Cash) | G18: Total
A19: =IFERROR((LOOKUP(MATCH(B19,'00 ACC DETAILS 03'!$E$30:$E$112,0),'00 ACC DETAILS 03'!$A$30:$A$112,'00 ACC DETAILS 03'!$D$30:$D$112)),0) | B19: 75-W | C19: =15*100 | D19: =A19*C19 | E19: =E21+12 | F19: =D19*E19/100 | G19: =D19+F19
A20: =IFERROR((LOOKUP(MATCH(B20,'00 ACC DETAILS 03'!$E$30:$E$112,0),'00 ACC DETAILS 03'!$A$30:$A$112,'00 ACC DETAILS 03'!$D$30:$D$112)),0) | B20: 76-D | C20: =15*150 | D20: =A20*C20 | E20: =E22+12 | F20: =D20*E20/100 | G20: =D20+F20
A21: =IFERROR((LOOKUP(MATCH(B21,'00 ACC DETAILS 03'!$E$30:$E$112,0),'00 ACC DETAILS 03'!$A$30:$A$112,'00 ACC DETAILS 03'!$D$30:$D$112)),0) | B21: 76-W | C21: =C19 | D21: =A21*C21 | E21: =E22+12 | F21: =D21*E21/100 | G21: =D21+F21
A22: =IFERROR((LOOKUP(MATCH(B22,'00 ACC DETAILS 03'!$E$30:$E$112,0),'00 ACC DETAILS 03'!$A$30:$A$112,'00 ACC DETAILS 03'!$D$30:$D$112)),0) | B22: 77-D | C22: =C20 | D22: =A22*C22 | E22: =E24+12 | F22: =D22*E22/100 | G22: =D22+F22
A23: =IFERROR((LOOKUP(MATCH(B23,'00 ACC DETAILS 03'!$E$30:$E$112,0),'00 ACC DETAILS 03'!$A$30:$A$112,'00 ACC DETAILS 03'!$D$30:$D$112)),0) | B23: 77-W | C23: =C21 | D23: =A23*C23 | E23: =E24+12 | F23: =D23*E23/100 | G23: =D23+F23
A24: =IFERROR((LOOKUP(MATCH(B24,'00 ACC DETAILS 03'!$E$30:$E$112,0),'00 ACC DETAILS 03'!$A$30:$A$112,'00 ACC DETAILS 03'!$D$30:$D$112)),0) | B24: 78-D | C24: =C22 | D24: =A24*C24 | E24: =E26+6 | F24: =D24*E24/100 | G24: =D24+F24
A25: =IFERROR((LOOKUP(MATCH(B25,'00 ACC DETAILS 03'!$E$30:$E$112,0),'00 ACC DETAILS 03'!$A$30:$A$112,'00 ACC DETAILS 03'!$D$30:$D$112)),0) | B25: 78-W | C25: =C23 | D25: =A25*C25 | E25: =E26+6 | F25: =D25*E25/100 | G25: =D25+F25
A26: =IFERROR((LOOKUP(MATCH(B26,'00 ACC DETAILS 03'!$E$30:$E$112,0),'00 ACC DETAILS 03'!$A$30:$A$112,'00 ACC DETAILS 03'!$D$30:$D$112)),0) | B26: 79-D | C26: =C24 | D26: =A26*C26 | E26: =E27+6 | F26: =D26*E26/100 | G26: =D26+F26
A27: =IFERROR((LOOKUP(MATCH(B27,'00 ACC DETAILS 03'!$E$30:$E$112,0),'00 ACC DETAILS 03'!$A$30:$A$112,'00 ACC DETAILS 03'!$D$30:$D$112)),0) | B27: 79-W | C27: =C25 | D27: =A27*C27 | E27: =E28+6 | F27: =D27*E27/100 | G27: =D27+F27
A28: =IFERROR((LOOKUP(MATCH(B28,'00 ACC DETAILS 03'!$E$30:$E$112,0),'00 ACC DETAILS 03'!$A$30:$A$112,'00 ACC DETAILS 03'!$D$30:$D$112)),0) | B28: 80-D | C28: =C26 | D28: =A28*C28 | E28: =E29+6 | F28: =D28*E28/100 | G28: =D28+F28
A29: =IFERROR((LOOKUP(MATCH(B29,'00 ACC DETAILS 03'!$E$30:$E$112,0),'00 ACC DETAILS 03'!$A$30:$A$112,'00 ACC DETAILS 03'!$D$30:$D$112)),0) | B29: 80-W | C29: =C27 | D29: =A29*C29 | E29: =E30+6 | F29: =D29*E29/100 | G29: =D29+F29
A30: =IFERROR((LOOKUP(MATCH(B30,'00 ACC DETAILS 03'!$E$30:$E$112,0),'00 ACC DETAILS 03'!$A$30:$A$112,'00 ACC DETAILS 03'!$D$30:$D$112)),0) | B30: 81-D | C30: =C28 | D30: =A30*C30 | E30: =E31+6 | F30: =D30*E30/100 | G30: =D30+F30
A31: =IFERROR((LOOKUP(MATCH(B31,'00 ACC DETAILS 03'!$E$30:$E$112,0),'00 ACC DETAILS 03'!$A$30:$A$112,'00 ACC DETAILS 03'!$D$30:$D$112)),0) | B31: 81-W | C31: =C29 | D31: =A31*C31 | E31: =E32+6 | F31: =D31*E31/100 | G31: =D31+F31
A32: =IFERROR((LOOKUP(MATCH(B32,'00 ACC DETAILS 03'!$E$30:$E$112,0),'00 ACC DETAILS 03'!$A$30:$A$112,'00 ACC DETAILS 03'!$D$30:$D$112)),0) | B32: 82-D | C32: =C30 | D32: =A32*C32 | E32: =E33+6 | F32: =D32*E32/100 | G32: =D32+F32
A33: =IFERROR((LOOKUP(MATCH(B33,'00 ACC DETAILS 03'!$E$30:$E$112,0),'00 ACC DETAILS 03'!$A$30:$A$112,'00 ACC DETAILS 03'!$D$30:$D$112)),0) | B33: 82-W | C33: =C31 | D33: =A33*C33 | E33: =E34+6 | F33: =D33*E33/100 | G33: =D33+F33
A34: =IFERROR((LOOKUP(MATCH(B34,'00 ACC DETAILS 03'!$E$30:$E$112,0),'00 ACC DETAILS 03'!$A$30:$A$112,'00 ACC DETAILS 03'!$D$30:$D$112)),0) | B34: 83-D | C34: =C32 | D34: =A34*C34 | E34: =E35+6 | F34: =D34*E34/100 | G34: =D34+F34
A35: =IFERROR((LOOKUP(MATCH(B35,'00 ACC DETAILS 03'!$E$30:$E$112,0),'00 ACC DETAILS 03'!$A$30:$A$112,'00 ACC DETAILS 03'!$D$30:$D$112)),0) | B35: 83-W | C35: =C33 | D35: =A35*C35 | E35: =E36+6 | F35: =D35*E35/100 | G35: =D35+F35
A36: =IFERROR((LOOKUP(MATCH(B36,'00 ACC DETAILS 03'!$E$30:$E$112,0),'00 ACC DETAILS 03'!$A$30:$A$112,'00 ACC DETAILS 03'!$D$30:$D$112)),0) | B36: 84-D | C36: =C34 | D36: =A36*C36 | E36: =E37+6 | F36: =D36*E36/100 | G36: =D36+F36
... A63: =IFERROR((LOOKUP(MATCH(B63,'00 ACC DETAILS 03'!$E$30:$E$112,0),'00 ACC DETAILS 03'!$A$30:$A$112,'00 ACC DETAILS 03'!$D$30:$D$112)),0) | B63: 97-W | C63: =C61 | D63: =A63*C63 | E63: =E64+6 | F63: =D63*E63/100 | G63: =D63+F63
A64: =IFERROR((LOOKUP(MATCH(B64,'00 ACC DETAILS 03'!$E$30:$E$112,0),'00 ACC DETAILS 03'!$A$30:$A$112,'00 ACC DETAILS 03'!$D$30:$D$112)),0) | B64: 98-D | C64: 0 | D64: =A64*C64 | E64: =E65+6 | F64: =D64*E64/100 | G64: =D64+F64
A65: =IFERROR((LOOKUP(MATCH(B65,'00 ACC DETAILS 03'!$E$30:$E$112,0),'00 ACC DETAILS 03'!$A$30:$A$112,'00 ACC DETAILS 03'!$D$30:$D$112)),0) | B65: 98-W | C65: 400 | D65: =A65*C65 | E65: =E66+6 | F65: =D65*E65/100 | G65: =D65+F65
A66: =IFERROR((LOOKUP(MATCH(B66,'00 ACC DETAILS 03'!$E$30:$E$112,0),'00 ACC DETAILS 03'!$A$30:$A$112,'00 ACC DETAILS 03'!$D$30:$D$112)),0) | B66: 99-D | C66: 600 | D66: =A66*C66 | E66: =E67+6 | F66: =D66*E66/100 | G66: =D66+F66
A67: =IFERROR((LOOKUP(MATCH(B67,'00 ACC DETAILS 03'!$E$30:$E$112,0),'00 ACC DETAILS 03'!$A$30:$A$112,'00 ACC DETAILS 03'!$D$30:$D$112)),0) | B67: 99-W | C67: 450 | D67: =A67*C67 | E67: =E68+6 | F67: =D67*E67/100 | G67: =D67+F67
A68: =IFERROR((LOOKUP(MATCH(B68,'00 ACC DETAILS 03'!$E$30:$E$112,0),'00 ACC DETAILS 03'!$A$30:$A$112,'00 ACC DETAILS 03'!$D$30:$D$112)),0) | B68: 2000-D | C68: 750 | D68: =A68*C68 | E68: =E69+6 | F68: =D68*E68/100 | G68: =D68+F68
A69: =IFERROR((LOOKUP(MATCH(B69,'00 ACC DETAILS 03'!$E$30:$E$112,0),'00 ACC DETAILS 03'!$A$30:$A$112,'00 ACC DETAILS 03'!$D$30:$D$112)),0) | B69: 2000-W | C69: =C67 | D69: =A69*C69 | E69: =E70+6 | F69: =D69*E69/100 | G69: =D69+F69
A70: =IFERROR((LOOKUP(MATCH(B70,'00 ACC DETAILS 03'!$E$30:$E$112,0),'00 ACC DETAILS 03'!$A$30:$A$112,'00 ACC DETAILS 03'!$D$30:$D$112)),0) | B70: 2001-D | C70: =C68 | D70: =A70*C70 | E70: =E71+6 | F70: =D70*E70/100 | G70: =D70+F70
A71: =IFERROR((LOOKUP(MATCH(B71,'00 ACC DETAILS 03'!$E$30:$E$112,0),'00 ACC DETAILS 03'!$A$30:$A$112,'00 ACC DETAILS 03'!$D$30:$D$112)),0) | B71: 2001-W | C71: =C63 | D71: =A71*C71 | E71: =E72+6 | F71: =D71*E71/100 | G71: =D71+F71
A72: =IFERROR((LOOKUP(MATCH(B72,'00 ACC DETAILS 03'!$E$30:$E$112,0),'00 ACC DETAILS 03'!$A$30:$A$112,'00 ACC DETAILS 03'!$D$30:$D$112)),0) | B72: 2002-D | C72: =C62 | D72: =A72*C72 | E72: =E73+6 | F72: =D72*E72/100 | G72: =D72+F72
A73: =IFERROR((LOOKUP(MATCH(B73,'00 ACC DETAILS 03'!$E$30:$E$112,0),'00 ACC DETAILS 03'!$A$30:$A$112,'00 ACC DETAILS 03'!$D$30:$D$112)),0) | B73: 2002-W | C73: =C71 | D73: =A73*C73 | E73: =E74+6 | F73: =D73*E73/100 | G73: =D73+F73
A74: =IFERROR((LOOKUP(MATCH(B74,'00 ACC DETAILS 03'!$E$30:$E$112,0),'00 ACC DETAILS 03'!$A$30:$A$112,'00 ACC DETAILS 03'!$D$30:$D$112)),0) | B74: 2003-D | C74: =C72 | D74: =A74*C74 | E74: =E75+6 | F74: =D74*E74/100 | G74: =D74+F74
A75: =IFERROR((LOOKUP(MATCH(B75,'00 ACC DETAILS 03'!$E$30:$E$112,0),'00 ACC DETAILS 03'!$A$30:$A$112,'00 ACC DETAILS 03'!$D$30:$D$112)),0) | B75: 2003-W | C75: =C73 | D75: =A75*C75 | E75: =E76+6 | F75: =D75*E75/100 | G75: =D75+F75
A76: =IFERROR((LOOKUP(MATCH(B76,'00 ACC DETAILS 03'!$E$30:$E$112,0),'00 ACC DETAILS 03'!$A$30:$A$112,'00 ACC DETAILS 03'!$D$30:$D$112)),0) | B76: 2004-D | C76: =C74 | D76: =A76*C76 | E76: =E77+6 | F76: =D76*E76/100 | G76: =D76+F76
A77: =IFERROR((LOOKUP(MATCH(B77,'00 ACC DETAILS 03'!$E$30:$E$112,0),'00 ACC DETAILS 03'!$A$30:$A$112,'00 ACC DETAILS 03'!$D$30:$D$112)),0) | B77: 2004-W | C77: =C75 | D77: =A77*C77 | E77: =E78+6 | F77: =D77*E77/100 | G77: =D77+F77
...

Sheet 00 ACC DETAILS 04
B2: ACCOUNT DETAILS
B3: Lot No. | C3: 3809
B4: Division | C4: ='00 ACC DETAILS 01'!C4
B5: Name of IA | C5: ='00 ACC DETAILS 01'!C5
B6: Name of Land Owner
B7: First Name | C7: ='00 ACC DETAILS 01'!C7
B8: Middle Name | C8: ='00 ACC DETAILS 01'!C8
B9: Surname | C9: ='00 ACC DETAILS 01'!C9
B10: Name of Farmer/Land Tiller
B11: First Name | C11: MARCELO
B12: Middle Name
B13: Surname | C13: GUINTO
B14: Location of Lot
B15: Baranggay | C15: ='00 ACC DETAILS 01'!C15
B16: Municipality/City | C16: ='00 ACC DETAILS 01'!C16
B17: Province | C17: ='00 ACC DETAILS 01'!C17
B18: Address of Land Owner
B19: Baranggay | C19: ='00 ACC DETAILS 01'!C19
B20: Municipality/City | C20: ='00 ACC DETAILS 01'!C20
B21: Province | C21: ='00 ACC DETAILS 01'!C21
B22: Address of Farmer/Land Tiller
B23: Baranggay | C23: ='00 ACC DETAILS 01'!C23
B24: Municipality/City | C24: ='00 ACC DETAILS 01'!C24
B25: Province | C25: ='00 ACC DETAILS 01'!C25
A28: IRRIGATION FEE REGISTRY (IFR)
B29: Wet/Dry | C29: Year | D29: Area
A30: 1 | E30: =IF(ISBLANK(B30),0,IF(C30<2000,RIGHT(C30,2),C30)&"-"&IF(B30="wet","W","D"))
A31: 2 | E31: =IF(ISBLANK(B31),0,IF(C31<2000,RIGHT(C31,2),C31)&"-"&IF(B31="wet","W","D"))
A32: 3 | E32: =IF(ISBLANK(B32),0,IF(C32<2000,RIGHT(C32,2),C32)&"-"&IF(B32="wet","W","D"))
A33: 4 | E33: =IF(ISBLANK(B33),0,IF(C33<2000,RIGHT(C33,2),C33)&"-"&IF(B33="wet","W","D"))
A34: 5 | E34: =IF(ISBLANK(B34),0,IF(C34<2000,RIGHT(C34,2),C34)&"-"&IF(B34="wet","W","D"))
A35: 6 | E35: =IF(ISBLANK(B35),0,IF(C35<2000,RIGHT(C35,2),C35)&"-"&IF(B35="wet","W","D"))
A36: 7 | E36: =IF(ISBLANK(B36),0,IF(C36<2000,RIGHT(C36,2),C36)&"-"&IF(B36="wet","W","D"))
A37: 8 | E37: =IF(ISBLANK(B37),0,IF(C37<2000,RIGHT(C37,2),C37)&"-"&IF(B37="wet","W","D"))
A38: 9 | E38: =IF(ISBLANK(B38),0,IF(C38<2000,RIGHT(C38,2),C38)&"-"&IF(B38="wet","W","D"))
A39: 10 | E39: =IF(ISBLANK(B39),0,IF(C39<2000,RIGHT(C39,2),C39)&"-"&IF(B39="wet","W","D"))
A40: 11 | E40: =IF(ISBLANK(B40),0,IF(C40<2000,RIGHT(C40,2),C40)&"-"&IF(B40="wet","W","D"))
A41: 12 | E41: =IF(ISBLANK(B41),0,IF(C41<2000,RIGHT(C41,2),C41)&"-"&IF(B41="wet","W","D"))
... A112: 83 | E112: =IF(ISBLANK(B112),0,IF(C112<2000,RIGHT(C112,2),C112)&"-"&IF(B112="wet","W","D"))

Sheet 01 SOA 04
A11: STATEMENT OF ACCOUNT
A12: ="as of "&TEXT(TODAY(),"mmmm dd, yyyy")
A14: FARMER CODE NO.: | F14: WRFT Div. : | G14: ='00 ACC DETAILS 04'!C4&" - "&'00 ACC DETAILS 04'!C5
A15: Lot No.: | C15: ='00 ACC DETAILS 04'!C3 | F15: Area:. | G15: {=IFERROR(0,LOOKUP(2,1/(A19:A101),A19:A101))}
A16: Name of Landowner: | C16: =IF(ISBLANK('00 ACC DETAILS 01'!C8),'00 ACC DETAILS 01'!C7&" "&'00 ACC DETAILS 01'!C9,'00 ACC DETAILS 01'!C7&" "&'00 ACC DETAILS 01'!C8&" "&'00 ACC DETAILS 01'!C9) | E16: Address:
A17: Name of Farmers: | C17: =IF(ISBLANK('00 ACC DETAILS 04'!C12),'00 ACC DETAILS 04'!C11&" "&'00 ACC DETAILS 04'!C13,'00 ACC DETAILS 04'!C11&" "&'00 ACC DETAILS 04'!C12&" "&'00 ACC DETAILS 04'!C13) | E17: Address:
A18: Area | B18: C. S. | C18: Rate | D18: Principal | E18: %Penalty | F18: Penalty(Cash) | G18: Total
A19: =IFERROR((LOOKUP(MATCH(B19,'00 ACC DETAILS 04'!$E$30:$E$112,0),'00 ACC DETAILS 04'!$A$30:$A$112,'00 ACC DETAILS 04'!$D$30:$D$112)),0) | B19: 75-W | C19: =15*100 | D19: =A19*C19 | E19: =E21+12 | F19: =D19*E19/100 | G19: =D19+F19
A20: =IFERROR((LOOKUP(MATCH(B20,'00 ACC DETAILS 04'!$E$30:$E$112,0),'00 ACC DETAILS 04'!$A$30:$A$112,'00 ACC DETAILS 04'!$D$30:$D$112)),0) | B20: 76-D | C20: =15*150 | D20: =A20*C20 | E20: =E22+12 | F20: =D20*E20/100 | G20: =D20+F20
A21: =IFERROR((LOOKUP(MATCH(B21,'00 ACC DETAILS 04'!$E$30:$E$112,0),'00 ACC DETAILS 04'!$A$30:$A$112,'00 ACC DETAILS 04'!$D$30:$D$112)),0) | B21: 76-W | C21: =C19 | D21: =A21*C21 | E21: =E22+12 | F21: =D21*E21/100 | G21: =D21+F21
A22: =IFERROR((LOOKUP(MATCH(B22,'00 ACC DETAILS 04'!$E$30:$E$112,0),'00 ACC DETAILS 04'!$A$30:$A$112,'00 ACC DETAILS 04'!$D$30:$D$112)),0) | B22: 77-D | C22: =C20 | D22: =A22*C22 | E22: =E24+12 | F22: =D22*E22/100 | G22: =D22+F22
A23: =IFERROR((LOOKUP(MATCH(B23,'00 ACC DETAILS 04'!$E$30:$E$112,0),'00 ACC DETAILS 04'!$A$30:$A$112,'00 ACC DETAILS 04'!$D$30:$D$112)),0) | B23: 77-W | C23: =C21 | D23: =A23*C23 | E23: =E24+12 | F23: =D23*E23/100 | G23: =D23+F23
A24: =IFERROR((LOOKUP(MATCH(B24,'00 ACC DETAILS 04'!$E$30:$E$112,0),'00 ACC DETAILS 04'!$A$30:$A$112,'00 ACC DETAILS 04'!$D$30:$D$112)),0) | B24: 78-D | C24: =C22 | D24: =A24*C24 | E24: =E26+6 | F24: =D24*E24/100 | G24: =D24+F24
A25: =IFERROR((LOOKUP(MATCH(B25,'00 ACC DETAILS 04'!$E$30:$E$112,0),'00 ACC DETAILS 04'!$A$30:$A$112,'00 ACC DETAILS 04'!$D$30:$D$112)),0) | B25: 78-W | C25: =C23 | D25: =A25*C25 | E25: =E26+6 | F25: =D25*E25/100 | G25: =D25+F25
A26: =IFERROR((LOOKUP(MATCH(B26,'00 ACC DETAILS 04'!$E$30:$E$112,0),'00 ACC DETAILS 04'!$A$30:$A$112,'00 ACC DETAILS 04'!$D$30:$D$112)),0) | B26: 79-D | C26: =C24 | D26: =A26*C26 | E26: =E27+6 | F26: =D26*E26/100 | G26: =D26+F26
A27: =IFERROR((LOOKUP(MATCH(B27,'00 ACC DETAILS 04'!$E$30:$E$112,0),'00 ACC DETAILS 04'!$A$30:$A$112,'00 ACC DETAILS 04'!$D$30:$D$112)),0) | B27: 79-W | C27: =C25 | D27: =A27*C27 | E27: =E28+6 | F27: =D27*E27/100 | G27: =D27+F27
A28: =IFERROR((LOOKUP(MATCH(B28,'00 ACC DETAILS 04'!$E$30:$E$112,0),'00 ACC DETAILS 04'!$A$30:$A$112,'00 ACC DETAILS 04'!$D$30:$D$112)),0) | B28: 80-D | C28: =C26 | D28: =A28*C28 | E28: =E29+6 | F28: =D28*E28/100 | G28: =D28+F28
A29: =IFERROR((LOOKUP(MATCH(B29,'00 ACC DETAILS 04'!$E$30:$E$112,0),'00 ACC DETAILS 04'!$A$30:$A$112,'00 ACC DETAILS 04'!$D$30:$D$112)),0) | B29: 80-W | C29: =C27 | D29: =A29*C29 | E29: =E30+6 | F29: =D29*E29/100 | G29: =D29+F29
A30: =IFERROR((LOOKUP(MATCH(B30,'00 ACC DETAILS 04'!$E$30:$E$112,0),'00 ACC DETAILS 04'!$A$30:$A$112,'00 ACC DETAILS 04'!$D$30:$D$112)),0) | B30: 81-D | C30: =C28 | D30: =A30*C30 | E30: =E31+6 | F30: =D30*E30/100 | G30: =D30+F30
A31: =IFERROR((LOOKUP(MATCH(B31,'00 ACC DETAILS 04'!$E$30:$E$112,0),'00 ACC DETAILS 04'!$A$30:$A$112,'00 ACC DETAILS 04'!$D$30:$D$112)),0) | B31: 81-W | C31: =C29 | D31: =A31*C31 | E31: =E32+6 | F31: =D31*E31/100 | G31: =D31+F31
A32: =IFERROR((LOOKUP(MATCH(B32,'00 ACC DETAILS 04'!$E$30:$E$112,0),'00 ACC DETAILS 04'!$A$30:$A$112,'00 ACC DETAILS 04'!$D$30:$D$112)),0) | B32: 82-D | C32: =C30 | D32: =A32*C32 | E32: =E33+6 | F32: =D32*E32/100 | G32: =D32+F32
A33: =IFERROR((LOOKUP(MATCH(B33,'00 ACC DETAILS 04'!$E$30:$E$112,0),'00 ACC DETAILS 04'!$A$30:$A$112,'00 ACC DETAILS 04'!$D$30:$D$112)),0) | B33: 82-W | C33: =C31 | D33: =A33*C33 | E33: =E34+6 | F33: =D33*E33/100 | G33: =D33+F33
A34: =IFERROR((LOOKUP(MATCH(B34,'00 ACC DETAILS 04'!$E$30:$E$112,0),'00 ACC DETAILS 04'!$A$30:$A$112,'00 ACC DETAILS 04'!$D$30:$D$112)),0) | B34: 83-D | C34: =C32 | D34: =A34*C34 | E34: =E35+6 | F34: =D34*E34/100 | G34: =D34+F34
A35: =IFERROR((LOOKUP(MATCH(B35,'00 ACC DETAILS 04'!$E$30:$E$112,0),'00 ACC DETAILS 04'!$A$30:$A$112,'00 ACC DETAILS 04'!$D$30:$D$112)),0) | B35: 83-W | C35: =C33 | D35: =A35*C35 | E35: =E36+6 | F35: =D35*E35/100 | G35: =D35+F35
A36: =IFERROR((LOOKUP(MATCH(B36,'00 ACC DETAILS 04'!$E$30:$E$112,0),'00 ACC DETAILS 04'!$A$30:$A$112,'00 ACC DETAILS 04'!$D$30:$D$112)),0) | B36: 84-D | C36: =C34 | D36: =A36*C36 | E36: =E37+6 | F36: =D36*E36/100 | G36: =D36+F36
... A63: =IFERROR((LOOKUP(MATCH(B63,'00 ACC DETAILS 04'!$E$30:$E$112,0),'00 ACC DETAILS 04'!$A$30:$A$112,'00 ACC DETAILS 04'!$D$30:$D$112)),0) | B63: 97-W | C63: =C61 | D63: =A63*C63 | E63: =E64+6 | F63: =D63*E63/100 | G63: =D63+F63
A64: =IFERROR((LOOKUP(MATCH(B64,'00 ACC DETAILS 04'!$E$30:$E$112,0),'00 ACC DETAILS 04'!$A$30:$A$112,'00 ACC DETAILS 04'!$D$30:$D$112)),0) | B64: 98-D | C64: 0 | D64: =A64*C64 | E64: =E65+6 | F64: =D64*E64/100 | G64: =D64+F64
A65: =IFERROR((LOOKUP(MATCH(B65,'00 ACC DETAILS 04'!$E$30:$E$112,0),'00 ACC DETAILS 04'!$A$30:$A$112,'00 ACC DETAILS 04'!$D$30:$D$112)),0) | B65: 98-W | C65: 400 | D65: =A65*C65 | E65: =E66+6 | F65: =D65*E65/100 | G65: =D65+F65
A66: =IFERROR((LOOKUP(MATCH(B66,'00 ACC DETAILS 04'!$E$30:$E$112,0),'00 ACC DETAILS 04'!$A$30:$A$112,'00 ACC DETAILS 04'!$D$30:$D$112)),0) | B66: 99-D | C66: 600 | D66: =A66*C66 | E66: =E67+6 | F66: =D66*E66/100 | G66: =D66+F66
A67: =IFERROR((LOOKUP(MATCH(B67,'00 ACC DETAILS 04'!$E$30:$E$112,0),'00 ACC DETAILS 04'!$A$30:$A$112,'00 ACC DETAILS 04'!$D$30:$D$112)),0) | B67: 99-W | C67: 450 | D67: =A67*C67 | E67: =E68+6 | F67: =D67*E67/100 | G67: =D67+F67
A68: =IFERROR((LOOKUP(MATCH(B68,'00 ACC DETAILS 04'!$E$30:$E$112,0),'00 ACC DETAILS 04'!$A$30:$A$112,'00 ACC DETAILS 04'!$D$30:$D$112)),0) | B68: 2000-D | C68: 750 | D68: =A68*C68 | E68: =E69+6 | F68: =D68*E68/100 | G68: =D68+F68
A69: =IFERROR((LOOKUP(MATCH(B69,'00 ACC DETAILS 04'!$E$30:$E$112,0),'00 ACC DETAILS 04'!$A$30:$A$112,'00 ACC DETAILS 04'!$D$30:$D$112)),0) | B69: 2000-W | C69: =C67 | D69: =A69*C69 | E69: =E70+6 | F69: =D69*E69/100 | G69: =D69+F69
A70: =IFERROR((LOOKUP(MATCH(B70,'00 ACC DETAILS 04'!$E$30:$E$112,0),'00 ACC DETAILS 04'!$A$30:$A$112,'00 ACC DETAILS 04'!$D$30:$D$112)),0) | B70: 2001-D | C70: =C68 | D70: =A70*C70 | E70: =E71+6 | F70: =D70*E70/100 | G70: =D70+F70
A71: =IFERROR((LOOKUP(MATCH(B71,'00 ACC DETAILS 04'!$E$30:$E$112,0),'00 ACC DETAILS 04'!$A$30:$A$112,'00 ACC DETAILS 04'!$D$30:$D$112)),0) | B71: 2001-W | C71: =C63 | D71: =A71*C71 | E71: =E72+6 | F71: =D71*E71/100 | G71: =D71+F71
A72: =IFERROR((LOOKUP(MATCH(B72,'00 ACC DETAILS 04'!$E$30:$E$112,0),'00 ACC DETAILS 04'!$A$30:$A$112,'00 ACC DETAILS 04'!$D$30:$D$112)),0) | B72: 2002-D | C72: =C62 | D72: =A72*C72 | E72: =E73+6 | F72: =D72*E72/100 | G72: =D72+F72
A73: =IFERROR((LOOKUP(MATCH(B73,'00 ACC DETAILS 04'!$E$30:$E$112,0),'00 ACC DETAILS 04'!$A$30:$A$112,'00 ACC DETAILS 04'!$D$30:$D$112)),0) | B73: 2002-W | C73: =C71 | D73: =A73*C73 | E73: =E74+6 | F73: =D73*E73/100 | G73: =D73+F73
A74: =IFERROR((LOOKUP(MATCH(B74,'00 ACC DETAILS 04'!$E$30:$E$112,0),'00 ACC DETAILS 04'!$A$30:$A$112,'00 ACC DETAILS 04'!$D$30:$D$112)),0) | B74: 2003-D | C74: =C72 | D74: =A74*C74 | E74: =E75+6 | F74: =D74*E74/100 | G74: =D74+F74
A75: =IFERROR((LOOKUP(MATCH(B75,'00 ACC DETAILS 04'!$E$30:$E$112,0),'00 ACC DETAILS 04'!$A$30:$A$112,'00 ACC DETAILS 04'!$D$30:$D$112)),0) | B75: 2003-W | C75: =C73 | D75: =A75*C75 | E75: =E76+6 | F75: =D75*E75/100 | G75: =D75+F75
A76: =IFERROR((LOOKUP(MATCH(B76,'00 ACC DETAILS 04'!$E$30:$E$112,0),'00 ACC DETAILS 04'!$A$30:$A$112,'00 ACC DETAILS 04'!$D$30:$D$112)),0) | B76: 2004-D | C76: =C74 | D76: =A76*C76 | E76: =E77+6 | F76: =D76*E76/100 | G76: =D76+F76
A77: =IFERROR((LOOKUP(MATCH(B77,'00 ACC DETAILS 04'!$E$30:$E$112,0),'00 ACC DETAILS 04'!$A$30:$A$112,'00 ACC DETAILS 04'!$D$30:$D$112)),0) | B77: 2004-W | C77: =C75 | D77: =A77*C77 | E77: =E78+6 | F77: =D77*E77/100 | G77: =D77+F77
...

Sheet 00 ACC DETAILS 05
B2: ACCOUNT DETAILS
B3: Lot No. | C3: 3809
B4: Division | C4: ='00 ACC DETAILS 01'!C4
B5: Name of IA | C5: ='00 ACC DETAILS 01'!C5
B6: Name of Land Owner
B7: First Name | C7: ='00 ACC DETAILS 01'!C7
B8: Middle Name | C8: ='00 ACC DETAILS 01'!C8
B9: Surname | C9: ='00 ACC DETAILS 01'!C9
B10: Name of Farmer/Land Tiller
B11: First Name | C11: MARCELO
B12: Middle Name
B13: Surname | C13: GUINTO
B14: Location of Lot
B15: Baranggay | C15: ='00 ACC DETAILS 01'!C15
B16: Municipality/City | C16: ='00 ACC DETAILS 01'!C16
B17: Province | C17: ='00 ACC DETAILS 01'!C17
B18: Address of Land Owner
B19: Baranggay | C19: ='00 ACC DETAILS 01'!C19
B20: Municipality/City | C20: ='00 ACC DETAILS 01'!C20
B21: Province | C21: ='00 ACC DETAILS 01'!C21
B22: Address of Farmer/Land Tiller
B23: Baranggay | C23: ='00 ACC DETAILS 01'!C23
B24: Municipality/City | C24: ='00 ACC DETAILS 01'!C24
B25: Province | C25: ='00 ACC DETAILS 01'!C25
A28: IRRIGATION FEE REGISTRY (IFR)
B29: Wet/Dry | C29: Year | D29: Area
A30: 1 | E30: =IF(ISBLANK(B30),0,IF(C30<2000,RIGHT(C30,2),C30)&"-"&IF(B30="wet","W","D"))
A31: 2 | E31: =IF(ISBLANK(B31),0,IF(C31<2000,RIGHT(C31,2),C31)&"-"&IF(B31="wet","W","D"))
A32: 3 | E32: =IF(ISBLANK(B32),0,IF(C32<2000,RIGHT(C32,2),C32)&"-"&IF(B32="wet","W","D"))
A33: 4 | E33: =IF(ISBLANK(B33),0,IF(C33<2000,RIGHT(C33,2),C33)&"-"&IF(B33="wet","W","D"))
A34: 5 | E34: =IF(ISBLANK(B34),0,IF(C34<2000,RIGHT(C34,2),C34)&"-"&IF(B34="wet","W","D"))
A35: 6 | E35: =IF(ISBLANK(B35),0,IF(C35<2000,RIGHT(C35,2),C35)&"-"&IF(B35="wet","W","D"))
A36: 7 | E36: =IF(ISBLANK(B36),0,IF(C36<2000,RIGHT(C36,2),C36)&"-"&IF(B36="wet","W","D"))
A37: 8 | E37: =IF(ISBLANK(B37),0,IF(C37<2000,RIGHT(C37,2),C37)&"-"&IF(B37="wet","W","D"))
A38: 9 | E38: =IF(ISBLANK(B38),0,IF(C38<2000,RIGHT(C38,2),C38)&"-"&IF(B38="wet","W","D"))
A39: 10 | E39: =IF(ISBLANK(B39),0,IF(C39<2000,RIGHT(C39,2),C39)&"-"&IF(B39="wet","W","D"))
A40: 11 | E40: =IF(ISBLANK(B40),0,IF(C40<2000,RIGHT(C40,2),C40)&"-"&IF(B40="wet","W","D"))
A41: 12 | E41: =IF(ISBLANK(B41),0,IF(C41<2000,RIGHT(C41,2),C41)&"-"&IF(B41="wet","W","D"))
... A112: 83 | E112: =IF(ISBLANK(B112),0,IF(C112<2000,RIGHT(C112,2),C112)&"-"&IF(B112="wet","W","D"))

Sheet 01 SOA 05
A11: STATEMENT OF ACCOUNT
A12: ="as of "&TEXT(TODAY(),"mmmm dd, yyyy")
A14: FARMER CODE NO.: | F14: WRFT Div. : | G14: ='00 ACC DETAILS 05'!C4&" - "&'00 ACC DETAILS 05'!C5
A15: Lot No.: | C15: ='00 ACC DETAILS 05'!C3 | F15: Area:. | G15: {=IFERROR(0,LOOKUP(2,1/(A19:A101),A19:A101))}
A16: Name of Landowner: | C16: =IF(ISBLANK('00 ACC DETAILS 01'!C8),'00 ACC DETAILS 01'!C7&" "&'00 ACC DETAILS 01'!C9,'00 ACC DETAILS 01'!C7&" "&'00 ACC DETAILS 01'!C8&" "&'00 ACC DETAILS 01'!C9) | E16: Address:
A17: Name of Farmers: | C17: =IF(ISBLANK('00 ACC DETAILS 05'!C12),'00 ACC DETAILS 05'!C11&" "&'00 ACC DETAILS 05'!C13,'00 ACC DETAILS 05'!C11&" "&'00 ACC DETAILS 05'!C12&" "&'00 ACC DETAILS 05'!C13) | E17: Address:
A18: Area | B18: C. S. | C18: Rate | D18: Principal | E18: %Penalty | F18: Penalty(Cash) | G18: Total
A19: =IFERROR((LOOKUP(MATCH(B19,'00 ACC DETAILS 05'!$E$30:$E$112,0),'00 ACC DETAILS 05'!$A$30:$A$112,'00 ACC DETAILS 05'!$D$30:$D$112)),0) | B19: 75-W | C19: =15*100 | D19: =A19*C19 | E19: =E21+12 | F19: =D19*E19/100 | G19: =D19+F19
A20: =IFERROR((LOOKUP(MATCH(B20,'00 ACC DETAILS 05'!$E$30:$E$112,0),'00 ACC DETAILS 05'!$A$30:$A$112,'00 ACC DETAILS 05'!$D$30:$D$112)),0) | B20: 76-D | C20: =15*150 | D20: =A20*C20 | E20: =E22+12 | F20: =D20*E20/100 | G20: =D20+F20
A21: =IFERROR((LOOKUP(MATCH(B21,'00 ACC DETAILS 05'!$E$30:$E$112,0),'00 ACC DETAILS 05'!$A$30:$A$112,'00 ACC DETAILS 05'!$D$30:$D$112)),0) | B21: 76-W | C21: =C19 | D21: =A21*C21 | E21: =E22+12 | F21: =D21*E21/100 | G21: =D21+F21
A22: =IFERROR((LOOKUP(MATCH(B22,'00 ACC DETAILS 05'!$E$30:$E$112,0),'00 ACC DETAILS 05'!$A$30:$A$112,'00 ACC DETAILS 05'!$D$30:$D$112)),0) | B22: 77-D | C22: =C20 | D22: =A22*C22 | E22: =E24+12 | F22: =D22*E22/100 | G22: =D22+F22
A23: =IFERROR((LOOKUP(MATCH(B23,'00 ACC DETAILS 05'!$E$30:$E$112,0),'00 ACC DETAILS 05'!$A$30:$A$112,'00 ACC DETAILS 05'!$D$30:$D$112)),0) | B23: 77-W | C23: =C21 | D23: =A23*C23 | E23: =E24+12 | F23: =D23*E23/100 | G23: =D23+F23
A24: =IFERROR((LOOKUP(MATCH(B24,'00 ACC DETAILS 05'!$E$30:$E$112,0),'00 ACC DETAILS 05'!$A$30:$A$112,'00 ACC DETAILS 05'!$D$30:$D$112)),0) | B24: 78-D | C24: =C22 | D24: =A24*C24 | E24: =E26+6 | F24: =D24*E24/100 | G24: =D24+F24
A25: =IFERROR((LOOKUP(MATCH(B25,'00 ACC DETAILS 05'!$E$30:$E$112,0),'00 ACC DETAILS 05'!$A$30:$A$112,'00 ACC DETAILS 05'!$D$30:$D$112)),0) | B25: 78-W | C25: =C23 | D25: =A25*C25 | E25: =E26+6 | F25: =D25*E25/100 | G25: =D25+F25
A26: =IFERROR((LOOKUP(MATCH(B26,'00 ACC DETAILS 05'!$E$30:$E$112,0),'00 ACC DETAILS 05'!$A$30:$A$112,'00 ACC DETAILS 05'!$D$30:$D$112)),0) | B26: 79-D | C26: =C24 | D26: =A26*C26 | E26: =E27+6 | F26: =D26*E26/100 | G26: =D26+F26
A27: =IFERROR((LOOKUP(MATCH(B27,'00 ACC DETAILS 05'!$E$30:$E$112,0),'00 ACC DETAILS 05'!$A$30:$A$112,'00 ACC DETAILS 05'!$D$30:$D$112)),0) | B27: 79-W | C27: =C25 | D27: =A27*C27 | E27: =E28+6 | F27: =D27*E27/100 | G27: =D27+F27
A28: =IFERROR((LOOKUP(MATCH(B28,'00 ACC DETAILS 05'!$E$30:$E$112,0),'00 ACC DETAILS 05'!$A$30:$A$112,'00 ACC DETAILS 05'!$D$30:$D$112)),0) | B28: 80-D | C28: =C26 | D28: =A28*C28 | E28: =E29+6 | F28: =D28*E28/100 | G28: =D28+F28
A29: =IFERROR((LOOKUP(MATCH(B29,'00 ACC DETAILS 05'!$E$30:$E$112,0),'00 ACC DETAILS 05'!$A$30:$A$112,'00 ACC DETAILS 05'!$D$30:$D$112)),0) | B29: 80-W | C29: =C27 | D29: =A29*C29 | E29: =E30+6 | F29: =D29*E29/100 | G29: =D29+F29
A30: =IFERROR((LOOKUP(MATCH(B30,'00 ACC DETAILS 05'!$E$30:$E$112,0),'00 ACC DETAILS 05'!$A$30:$A$112,'00 ACC DETAILS 05'!$D$30:$D$112)),0) | B30: 81-D | C30: =C28 | D30: =A30*C30 | E30: =E31+6 | F30: =D30*E30/100 | G30: =D30+F30
A31: =IFERROR((LOOKUP(MATCH(B31,'00 ACC DETAILS 05'!$E$30:$E$112,0),'00 ACC DETAILS 05'!$A$30:$A$112,'00 ACC DETAILS 05'!$D$30:$D$112)),0) | B31: 81-W | C31: =C29 | D31: =A31*C31 | E31: =E32+6 | F31: =D31*E31/100 | G31: =D31+F31
A32: =IFERROR((LOOKUP(MATCH(B32,'00 ACC DETAILS 05'!$E$30:$E$112,0),'00 ACC DETAILS 05'!$A$30:$A$112,'00 ACC DETAILS 05'!$D$30:$D$112)),0) | B32: 82-D | C32: =C30 | D32: =A32*C32 | E32: =E33+6 | F32: =D32*E32/100 | G32: =D32+F32
A33: =IFERROR((LOOKUP(MATCH(B33,'00 ACC DETAILS 05'!$E$30:$E$112,0),'00 ACC DETAILS 05'!$A$30:$A$112,'00 ACC DETAILS 05'!$D$30:$D$112)),0) | B33: 82-W | C33: =C31 | D33: =A33*C33 | E33: =E34+6 | F33: =D33*E33/100 | G33: =D33+F33
A34: =IFERROR((LOOKUP(MATCH(B34,'00 ACC DETAILS 05'!$E$30:$E$112,0),'00 ACC DETAILS 05'!$A$30:$A$112,'00 ACC DETAILS 05'!$D$30:$D$112)),0) | B34: 83-D | C34: =C32 | D34: =A34*C34 | E34: =E35+6 | F34: =D34*E34/100 | G34: =D34+F34
A35: =IFERROR((LOOKUP(MATCH(B35,'00 ACC DETAILS 05'!$E$30:$E$112,0),'00 ACC DETAILS 05'!$A$30:$A$112,'00 ACC DETAILS 05'!$D$30:$D$112)),0) | B35: 83-W | C35: =C33 | D35: =A35*C35 | E35: =E36+6 | F35: =D35*E35/100 | G35: =D35+F35
A36: =IFERROR((LOOKUP(MATCH(B36,'00 ACC DETAILS 05'!$E$30:$E$112,0),'00 ACC DETAILS 05'!$A$30:$A$112,'00 ACC DETAILS 05'!$D$30:$D$112)),0) | B36: 84-D | C36: =C34 | D36: =A36*C36 | E36: =E37+6 | F36: =D36*E36/100 | G36: =D36+F36
... A63: =IFERROR((LOOKUP(MATCH(B63,'00 ACC DETAILS 05'!$E$30:$E$112,0),'00 ACC DETAILS 05'!$A$30:$A$112,'00 ACC DETAILS 05'!$D$30:$D$112)),0) | B63: 97-W | C63: =C61 | D63: =A63*C63 | E63: =E64+6 | F63: =D63*E63/100 | G63: =D63+F63
A64: =IFERROR((LOOKUP(MATCH(B64,'00 ACC DETAILS 05'!$E$30:$E$112,0),'00 ACC DETAILS 05'!$A$30:$A$112,'00 ACC DETAILS 05'!$D$30:$D$112)),0) | B64: 98-D | C64: 0 | D64: =A64*C64 | E64: =E65+6 | F64: =D64*E64/100 | G64: =D64+F64
A65: =IFERROR((LOOKUP(MATCH(B65,'00 ACC DETAILS 05'!$E$30:$E$112,0),'00 ACC DETAILS 05'!$A$30:$A$112,'00 ACC DETAILS 05'!$D$30:$D$112)),0) | B65: 98-W | C65: 400 | D65: =A65*C65 | E65: =E66+6 | F65: =D65*E65/100 | G65: =D65+F65
A66: =IFERROR((LOOKUP(MATCH(B66,'00 ACC DETAILS 05'!$E$30:$E$112,0),'00 ACC DETAILS 05'!$A$30:$A$112,'00 ACC DETAILS 05'!$D$30:$D$112)),0) | B66: 99-D | C66: 600 | D66: =A66*C66 | E66: =E67+6 | F66: =D66*E66/100 | G66: =D66+F66
A67: =IFERROR((LOOKUP(MATCH(B67,'00 ACC DETAILS 05'!$E$30:$E$112,0),'00 ACC DETAILS 05'!$A$30:$A$112,'00 ACC DETAILS 05'!$D$30:$D$112)),0) | B67: 99-W | C67: 450 | D67: =A67*C67 | E67: =E68+6 | F67: =D67*E67/100 | G67: =D67+F67
A68: =IFERROR((LOOKUP(MATCH(B68,'00 ACC DETAILS 05'!$E$30:$E$112,0),'00 ACC DETAILS 05'!$A$30:$A$112,'00 ACC DETAILS 05'!$D$30:$D$112)),0) | B68: 2000-D | C68: 750 | D68: =A68*C68 | E68: =E69+6 | F68: =D68*E68/100 | G68: =D68+F68
A69: =IFERROR((LOOKUP(MATCH(B69,'00 ACC DETAILS 05'!$E$30:$E$112,0),'00 ACC DETAILS 05'!$A$30:$A$112,'00 ACC DETAILS 05'!$D$30:$D$112)),0) | B69: 2000-W | C69: =C67 | D69: =A69*C69 | E69: =E70+6 | F69: =D69*E69/100 | G69: =D69+F69
A70: =IFERROR((LOOKUP(MATCH(B70,'00 ACC DETAILS 05'!$E$30:$E$112,0),'00 ACC DETAILS 05'!$A$30:$A$112,'00 ACC DETAILS 05'!$D$30:$D$112)),0) | B70: 2001-D | C70: =C68 | D70: =A70*C70 | E70: =E71+6 | F70: =D70*E70/100 | G70: =D70+F70
A71: =IFERROR((LOOKUP(MATCH(B71,'00 ACC DETAILS 05'!$E$30:$E$112,0),'00 ACC DETAILS 05'!$A$30:$A$112,'00 ACC DETAILS 05'!$D$30:$D$112)),0) | B71: 2001-W | C71: =C63 | D71: =A71*C71 | E71: =E72+6 | F71: =D71*E71/100 | G71: =D71+F71
A72: =IFERROR((LOOKUP(MATCH(B72,'00 ACC DETAILS 05'!$E$30:$E$112,0),'00 ACC DETAILS 05'!$A$30:$A$112,'00 ACC DETAILS 05'!$D$30:$D$112)),0) | B72: 2002-D | C72: =C62 | D72: =A72*C72 | E72: =E73+6 | F72: =D72*E72/100 | G72: =D72+F72
A73: =IFERROR((LOOKUP(MATCH(B73,'00 ACC DETAILS 05'!$E$30:$E$112,0),'00 ACC DETAILS 05'!$A$30:$A$112,'00 ACC DETAILS 05'!$D$30:$D$112)),0) | B73: 2002-W | C73: =C71 | D73: =A73*C73 | E73: =E74+6 | F73: =D73*E73/100 | G73: =D73+F73
A74: =IFERROR((LOOKUP(MATCH(B74,'00 ACC DETAILS 05'!$E$30:$E$112,0),'00 ACC DETAILS 05'!$A$30:$A$112,'00 ACC DETAILS 05'!$D$30:$D$112)),0) | B74: 2003-D | C74: =C72 | D74: =A74*C74 | E74: =E75+6 | F74: =D74*E74/100 | G74: =D74+F74
A75: =IFERROR((LOOKUP(MATCH(B75,'00 ACC DETAILS 05'!$E$30:$E$112,0),'00 ACC DETAILS 05'!$A$30:$A$112,'00 ACC DETAILS 05'!$D$30:$D$112)),0) | B75: 2003-W | C75: =C73 | D75: =A75*C75 | E75: =E76+6 | F75: =D75*E75/100 | G75: =D75+F75
A76: =IFERROR((LOOKUP(MATCH(B76,'00 ACC DETAILS 05'!$E$30:$E$112,0),'00 ACC DETAILS 05'!$A$30:$A$112,'00 ACC DETAILS 05'!$D$30:$D$112)),0) | B76: 2004-D | C76: =C74 | D76: =A76*C76 | E76: =E77+6 | F76: =D76*E76/100 | G76: =D76+F76
A77: =IFERROR((LOOKUP(MATCH(B77,'00 ACC DETAILS 05'!$E$30:$E$112,0),'00 ACC DETAILS 05'!$A$30:$A$112,'00 ACC DETAILS 05'!$D$30:$D$112)),0) | B77: 2004-W | C77: =C75 | D77: =A77*C77 | E77: =E78+6 | F77: =D77*E77/100 | G77: =D77+F77
...

Sheet 02 REGISTRY
V1: Form 1
A2: REPUBLIC OF THE PHILIPPINES
A3: NATIONAL IRRIGATION ADMINISTRATION
A4: REGIONAL OFFICE NO. III (CENTRAL LUZON)
A5: BULACAN IRRIGATION MANAGEMENT OFFICE
A10: REGISTRY OF LANDOWNERS, FARMERS, AND OTHER IRRIGATION WATER USERS
A11: ="(1) As of "&TEXT(TODAY(),"mmmm dd, yyyy")
A13: (2) | B13: Region: III | M13: ="(5) Name of IA : "&'00 ACC DETAILS 01'!C5
A14: (3) | B14: IMO: BULACAN | M14: (6) Turnout Service Area Group/Sector No. or Name:
A15: (4) | B15: Name of NIS/CIS: AMRIS | M15: ="(7) Supply Canal: (8) Station : "&'00 ACC DETAILS 01'!C4
A17: Lot Number | C17: Lot Area (ha) | D17: Location of Lot | G17: Proof of Ownership | H17: Name of Landowner | K17: Address of Landowner | N17: Name of Farmer (ActualTiller) or Water User | Q17: Address of Farmer (ActualTiller) or Water User | T17: Status of Exemption | V17: REMARKS
C19: (10) | D19: Barangay | E19: Municipality/ City | F19: Province | G19: (12) | H19: Family Name | I19: First Name | J19: Middle Name | K19: Barangay | L19: Municipality/ City | M19: Province | N19: Family Name | O19: First Name | P19: Middle Name | Q19: Barangay | R19: Municipality/ City | S19: Province | T19: Exempted | U19: Not Exempted
A20: (9) | C20: (10) | D20: (11) | E20: (12) | F20: (13) | G20: (14) | H20: (15) | I20: (16) | J20: (17) | K20: (18) | L20: (19) | M20: (20) | N20: (21) | O20: (22) | P20: (23) | Q20: (24) | R20: (25) | S20: (26) | T20: (27) | U20: (28) | V20: (29)
A21: ='00 ACC DETAILS 01'!C3 | C21: ='01 SOA 01'!G13 | D21: ='00 ACC DETAILS 01'!C15 | E21: ='00 ACC DETAILS 01'!C16 | F21: ='00 ACC DETAILS 01'!C17 | H21: ='00 ACC DETAILS 01'!C9 | I21: ='00 ACC DETAILS 01'!C7 | J21: ='00 ACC DETAILS 01'!C8 | K21: ='00 ACC DETAILS 01'!C19 | L21: ='00 ACC DETAILS 01'!C20 | M21: ='00 ACC DETAILS 01'!C21 | N21: ='00 ACC DETAILS 01'!C13 | O21: ='00 ACC DETAILS 01'!C11 | P21: ='00 ACC DETAILS 01'!C12 | Q21: ='00 ACC DETAILS 01'!C23 | R21: ='00 ACC DETAILS 01'!C24 | S21: ='00 ACC DETAILS 01'!C25 | T21: ü
A22: ='00 ACC DETAILS 02'!C3 | C22: ='01 SOA 02'!G15 | D22: ='00 ACC DETAILS 02'!C15 | E22: ='00 ACC DETAILS 02'!C16 | F22: ='00 ACC DETAILS 02'!C17 | H22: ='00 ACC DETAILS 02'!C9 | I22: ='00 ACC DETAILS 02'!C7 | J22: ='00 ACC DETAILS 02'!C8 | K22: ='00 ACC DETAILS 02'!C19 | L22: ='00 ACC DETAILS 02'!C20 | M22: ='00 ACC DETAILS 02'!C21 | N22: ='00 ACC DETAILS 02'!C13 | O22: ='00 ACC DETAILS 02'!C11 | P22: ='00 ACC DETAILS 02'!C12 | Q22: ='00 ACC DETAILS 02'!C23 | R22: ='00 ACC DETAILS 02'!C24 | S22: ='00 ACC DETAILS 02'!C25 | T22: ü
A23: ='00 ACC DETAILS 03'!C3 | C23: ='01 SOA 03'!G15 | D23: ='00 ACC DETAILS 03'!C15 | E23: ='00 ACC DETAILS 03'!C16 | F23: ='00 ACC DETAILS 03'!C17 | H23: ='00 ACC DETAILS 03'!C9 | I23: ='00 ACC DETAILS 03'!C7 | J23: ='00 ACC DETAILS 03'!C8 | K23: ='00 ACC DETAILS 03'!C19 | L23: ='00 ACC DETAILS 03'!C20 | M23: ='00 ACC DETAILS 03'!C21 | N23: ='00 ACC DETAILS 03'!C13 | O23: ='00 ACC DETAILS 03'!C11 | P23: ='00 ACC DETAILS 03'!C12 | Q23: ='00 ACC DETAILS 03'!C23 | R23: ='00 ACC DETAILS 03'!C24 | S23: ='00 ACC DETAILS 03'!C25 | T23: ü
A24: ='00 ACC DETAILS 04'!C3 | C24: ='01 SOA 04'!G15 | D24: ='00 ACC DETAILS 04'!C15 | E24: ='00 ACC DETAILS 04'!C16 | F24: ='00 ACC DETAILS 04'!C17 | H24: ='00 ACC DETAILS 04'!C9 | I24: ='00 ACC DETAILS 04'!C7 | J24: ='00 ACC DETAILS 04'!C8 | K24: ='00 ACC DETAILS 04'!C19 | L24: ='00 ACC DETAILS 04'!C20 | M24: ='00 ACC DETAILS 04'!C21 | N24: ='00 ACC DETAILS 04'!C13 | O24: ='00 ACC DETAILS 04'!C11 | P24: ='00 ACC DETAILS 04'!C12 | Q24: ='00 ACC DETAILS 04'!C23 | R24: ='00 ACC DETAILS 04'!C24 | S24: ='00 ACC DETAILS 04'!C25 | T24: ü
A25: ='00 ACC DETAILS 05'!C3 | C25: ='01 SOA 05'!G15 | D25: ='00 ACC DETAILS 05'!C15 | E25: ='00 ACC DETAILS 05'!C16 | F25: ='00 ACC DETAILS 05'!C17 | H25: ='00 ACC DETAILS 05'!C9 | I25: ='00 ACC DETAILS 05'!C7 | J25: ='00 ACC DETAILS 05'!C8 | K25: ='00 ACC DETAILS 05'!C19 | L25: ='00 ACC DETAILS 05'!C20 | M25: ='00 ACC DETAILS 05'!C21 | N25: ='00 ACC DETAILS 05'!C13 | O25: ='00 ACC DETAILS 05'!C11 | P25: ='00 ACC DETAILS 05'!C12 | Q25: ='00 ACC DETAILS 05'!C23 | R25: ='00 ACC DETAILS 05'!C24 | S25: ='00 ACC DETAILS 05'!C25 | T25: ü
A27: TOTAL | C27: =SUM(C21:C26)
A29: Prepared by: | I29: Submitted by: | Q29: Approved by:
C31: CATHERINE DC. AUSTRIA | J31: LEOPOLDO Q. MANIEGO | R31: ROBERTO J. DELA CRUZ
C32: Accounting Processor A | J32: Chief, O & M Section | R32: Manager, BULACAN IMO

Sheet 03 PARTIAL LIST
A1: PARTIAL LIST OF FARMERS AVAIL FOR CONDONATION
A3: ="DIVISION "&'00 ACC DETAILS 01'!C4
A4: LOT NO. | B4: AREA | C4: LANDOWNER | D4: TILLER | E4: UNPAID ISF
E5: PRINCIPAL | F5: PENALTY | G5: PRIOR | H5: TOTAL
A6: ='00 ACC DETAILS 01'!C3 | B6: ='01 SOA 01'!G13 | C6: ='01 SOA 01'!C14 | D6: ='01 SOA 01'!C15 | E6: ='01 SOA 01'!D100 | F6: ='01 SOA 01'!F100 | G6: ='01 SOA 01'!G101 | H6: ='01 SOA 01'!G100
A7: ='00 ACC DETAILS 02'!C3 | B7: ='01 SOA 02'!G15 | C7: ='01 SOA 02'!C16 | D7: ='01 SOA 02'!C17 | E7: ='01 SOA 02'!D102 | F7: ='01 SOA 02'!F102 | G7: ='01 SOA 02'!G103 | H7: ='01 SOA 02'!G102
A8: ='00 ACC DETAILS 03'!C3 | B8: ='01 SOA 03'!G15 | C8: ='01 SOA 03'!C16 | D8: ='01 SOA 03'!C17 | E8: ='01 SOA 03'!D102 | F8: ='01 SOA 03'!F102 | G8: ='01 SOA 03'!G103 | H8: ='01 SOA 03'!G102
A9: ='00 ACC DETAILS 04'!C3 | B9: ='01 SOA 04'!G15 | C9: ='01 SOA 04'!C16 | D9: ='01 SOA 04'!C17 | E9: ='01 SOA 04'!D102 | F9: ='01 SOA 04'!F102 | G9: ='01 SOA 04'!G103 | H9: ='01 SOA 04'!G102
A10: ='00 ACC DETAILS 05'!C3 | B10: ='01 SOA 05'!G15 | C10: ='01 SOA 05'!C16 | D10: ='01 SOA 05'!C17 | E10: ='01 SOA 05'!D102 | F10: ='01 SOA 05'!F102 | G10: ='01 SOA 05'!G103 | H10: ='01 SOA 05'!G102
A12: TOTAL | B12: =SUM(B6:B11) | E12: =SUM(E6:E11) | F12: =SUM(F6:F11) | G12: =SUM(G6:G11) | H12: =SUM(H6:H11)
A15: Prepared by: | C15: Submitted by: | F15: Approved by:
A18: CATHERINE DC. AUSTRIA | D18: LEOPOLDO Q. MANIEGO | G18: ROBERTO J. DELA CRUZ
A19: Accounting Processor A | D19: Chief, O & M Section | G19: Manager, BULACAN IMO

Sheet 04 IRR FISA FORM 2
A1: REPUBLIC OF THE PHILIPPINES
A2: NATIONAL IRRIGATION ADMINISTRATION
A3: REGIONAL OFFICE NO. III (CENTRAL LUZON)
A4: BULACAN IRRIGATION MANAGEMENT OFFICE
Y7: IRR FISA Form 2
A9: STATEMENT OF ACCOUNT FOR UNPAID IRRIGATION SERVICE FEE (ISF) OF EXEMPT LANDOWNERS/FARMERS PER RA 10969 as of February 24, 2018
A11: Name of Irrigation System: AMRIS
A12: IMO: BULACAN IMO
A13: Region: III
A14: Name of Landowner (First, Middle, Family): | L14: ='03 PARTIAL LIST'!C6
A15: Address of Landowner (Barangay, Municipality/City, Province): | Q15: =PROPER('00 ACC DETAILS 01'!C19&", "&'00 ACC DETAILS 01'!C20&", "&'00 ACC DETAILS 01'!C21)
A16: Name of Actual Tiller/Farmer (First, Middle, Family): | N16: ='03 PARTIAL LIST'!D6
A17: Address of Actual Tiller/Farmer (Barangay, Municipality/City, Province): | S17: =PROPER('00 ACC DETAILS 01'!C23&", "&'00 ACC DETAILS 01'!C24&", "&'00 ACC DETAILS 01'!C25)
A19: LOT NO. | C19: AREA | E19: Location of Lot (Barangay, Municipality/City, Province) | Q19: Accumulated Unpaid ISF (P) 1/
Q20: PRINCIPAL | U20: INTEREST | W20: PENALTIES | Z20: TOTAL
